{
 "cells": [
  {
   "cell_type": "markdown",
   "id": "ef2bfb16",
   "metadata": {},
   "source": [
    "# Milestone Project #1"
   ]
  },
  {
   "cell_type": "code",
   "execution_count": 1,
   "id": "9af1d561",
   "metadata": {},
   "outputs": [],
   "source": [
    "import dash\n",
    "from dash import dcc\n",
    "from dash import html\n",
    "import plotly.graph_objs as pgo\n",
    "import numpy as np\n",
    "import pandas as pd\n",
    "from dash.dependencies import Input, Output"
   ]
  },
  {
   "cell_type": "code",
   "execution_count": null,
   "id": "43931420",
   "metadata": {},
   "outputs": [],
   "source": [
    "!pip install pandas-datareader"
   ]
  },
  {
   "cell_type": "code",
   "execution_count": 2,
   "id": "fd051b1b",
   "metadata": {},
   "outputs": [],
   "source": [
    "import pandas_datareader.data as pdd\n",
    "from datetime import datetime"
   ]
  },
  {
   "cell_type": "code",
   "execution_count": 3,
   "id": "4a477ee7",
   "metadata": {},
   "outputs": [],
   "source": [
    "import os\n",
    "os.environ[\"IEX_API_KEY\"] = \"pk_e124697d80704446893c52da182883c8\" #API key"
   ]
  },
  {
   "cell_type": "code",
   "execution_count": null,
   "id": "e97f7cef",
   "metadata": {
    "scrolled": true
   },
   "outputs": [
    {
     "name": "stdout",
     "output_type": "stream",
     "text": [
      "Dash is running on http://127.0.0.1:8050/\n",
      "\n",
      " * Serving Flask app \"__main__\" (lazy loading)\n",
      " * Environment: production\n",
      "\u001b[31m   WARNING: This is a development server. Do not use it in a production deployment.\u001b[0m\n",
      "\u001b[2m   Use a production WSGI server instead.\u001b[0m\n",
      " * Debug mode: off\n"
     ]
    },
    {
     "name": "stderr",
     "output_type": "stream",
     "text": [
      " * Running on http://127.0.0.1:8050/ (Press CTRL+C to quit)\n",
      "127.0.0.1 - - [03/Jan/2023 01:57:30] \"GET / HTTP/1.1\" 200 -\n",
      "127.0.0.1 - - [03/Jan/2023 01:57:34] \"GET /_dash-dependencies HTTP/1.1\" 200 -\n",
      "127.0.0.1 - - [03/Jan/2023 01:57:34] \"GET /_dash-layout HTTP/1.1\" 200 -\n",
      "127.0.0.1 - - [03/Jan/2023 01:57:34] \"GET /_dash-component-suites/dash/dcc/async-plotlyjs.js HTTP/1.1\" 200 -\n",
      "127.0.0.1 - - [03/Jan/2023 01:57:34] \"GET /_dash-component-suites/dash/dcc/async-graph.js HTTP/1.1\" 200 -\n",
      "127.0.0.1 - - [03/Jan/2023 01:57:40] \"POST /_dash-update-component HTTP/1.1\" 200 -\n",
      "127.0.0.1 - - [03/Jan/2023 01:57:43] \"POST /_dash-update-component HTTP/1.1\" 200 -\n",
      "127.0.0.1 - - [03/Jan/2023 01:57:44] \"POST /_dash-update-component HTTP/1.1\" 200 -\n",
      "127.0.0.1 - - [03/Jan/2023 01:57:45] \"POST /_dash-update-component HTTP/1.1\" 200 -\n",
      "127.0.0.1 - - [03/Jan/2023 01:57:48] \"POST /_dash-update-component HTTP/1.1\" 200 -\n",
      "127.0.0.1 - - [03/Jan/2023 01:58:02] \"POST /_dash-update-component HTTP/1.1\" 200 -\n",
      "127.0.0.1 - - [03/Jan/2023 01:58:03] \"POST /_dash-update-component HTTP/1.1\" 200 -\n"
     ]
    },
    {
     "name": "stdout",
     "output_type": "stream",
     "text": [
      "Exception on /_dash-update-component [POST]\n",
      "Traceback (most recent call last):\n",
      "  File \"C:\\Users\\admin\\anaconda3\\lib\\site-packages\\flask\\app.py\", line 2447, in wsgi_app\n",
      "    response = self.full_dispatch_request()\n",
      "  File \"C:\\Users\\admin\\anaconda3\\lib\\site-packages\\flask\\app.py\", line 1952, in full_dispatch_request\n",
      "    rv = self.handle_user_exception(e)\n",
      "  File \"C:\\Users\\admin\\anaconda3\\lib\\site-packages\\flask\\app.py\", line 1821, in handle_user_exception\n",
      "    reraise(exc_type, exc_value, tb)\n",
      "  File \"C:\\Users\\admin\\anaconda3\\lib\\site-packages\\flask\\_compat.py\", line 39, in reraise\n",
      "    raise value\n",
      "  File \"C:\\Users\\admin\\anaconda3\\lib\\site-packages\\flask\\app.py\", line 1950, in full_dispatch_request\n",
      "    rv = self.dispatch_request()\n",
      "  File \"C:\\Users\\admin\\anaconda3\\lib\\site-packages\\flask\\app.py\", line 1936, in dispatch_request\n",
      "    return self.view_functions[rule.endpoint](**req.view_args)\n",
      "  File \"C:\\Users\\admin\\anaconda3\\lib\\site-packages\\dash\\dash.py\", line 1274, in dispatch\n",
      "    ctx.run(\n",
      "  File \"C:\\Users\\admin\\anaconda3\\lib\\site-packages\\dash\\_callback.py\", line 440, in add_context\n",
      "    output_value = func(*func_args, **func_kwargs)  # %% callback invoked %%\n",
      "  File \"C:\\Users\\admin\\AppData\\Local\\Temp\\ipykernel_16924\\2990508254.py\", line 19, in stock_update\n",
      "    df=pdd.DataReader(stock_ticker,'iex',start,end)\n",
      "  File \"C:\\Users\\admin\\anaconda3\\lib\\site-packages\\pandas\\util\\_decorators.py\", line 207, in wrapper\n",
      "    return func(*args, **kwargs)\n",
      "  File \"C:\\Users\\admin\\anaconda3\\lib\\site-packages\\pandas_datareader\\data.py\", line 382, in DataReader\n",
      "    return IEXDailyReader(\n",
      "  File \"C:\\Users\\admin\\anaconda3\\lib\\site-packages\\pandas_datareader\\iex\\daily.py\", line 143, in read\n",
      "    return self._read_one_data(self.url, self._get_params(self.symbols))\n",
      "  File \"C:\\Users\\admin\\anaconda3\\lib\\site-packages\\pandas_datareader\\base.py\", line 108, in _read_one_data\n",
      "    out = self._read_url_as_StringIO(url, params=params)\n",
      "  File \"C:\\Users\\admin\\anaconda3\\lib\\site-packages\\pandas_datareader\\base.py\", line 119, in _read_url_as_StringIO\n",
      "    response = self._get_response(url, params=params)\n",
      "  File \"C:\\Users\\admin\\anaconda3\\lib\\site-packages\\pandas_datareader\\base.py\", line 181, in _get_response\n",
      "    raise RemoteDataError(msg)\n",
      "pandas_datareader._utils.RemoteDataError: Unable to read URL: https://cloud.iexapis.com/stable/stock/market/batch?symbols=&types=chart&range=max&token=pk_e124697d80704446893c52da182883c8\n",
      "Response Text:\n",
      "b'{\"error\":\"\\\\\"symbols\\\\\" is not allowed to be empty\"}'\n"
     ]
    },
    {
     "name": "stderr",
     "output_type": "stream",
     "text": [
      "127.0.0.1 - - [03/Jan/2023 01:58:04] \"POST /_dash-update-component HTTP/1.1\" 500 -\n",
      "127.0.0.1 - - [03/Jan/2023 01:58:07] \"GET / HTTP/1.1\" 200 -\n",
      "127.0.0.1 - - [03/Jan/2023 01:58:09] \"POST /_dash-update-component HTTP/1.1\" 200 -\n",
      "127.0.0.1 - - [03/Jan/2023 01:58:09] \"GET /_dash-layout HTTP/1.1\" 200 -\n",
      "127.0.0.1 - - [03/Jan/2023 01:58:09] \"GET /_dash-dependencies HTTP/1.1\" 200 -\n",
      "127.0.0.1 - - [03/Jan/2023 01:58:09] \"GET /_favicon.ico?v=2.7.0 HTTP/1.1\" 200 -\n",
      "127.0.0.1 - - [03/Jan/2023 01:58:09] \"GET /_dash-component-suites/dash/dcc/async-graph.js HTTP/1.1\" 200 -\n",
      "127.0.0.1 - - [03/Jan/2023 01:58:09] \"GET /_dash-component-suites/dash/dcc/async-plotlyjs.js HTTP/1.1\" 200 -\n",
      "127.0.0.1 - - [03/Jan/2023 01:58:13] \"POST /_dash-update-component HTTP/1.1\" 200 -\n"
     ]
    },
    {
     "name": "stdout",
     "output_type": "stream",
     "text": [
      "Exception on /_dash-update-component [POST]\n",
      "Traceback (most recent call last):\n",
      "  File \"C:\\Users\\admin\\anaconda3\\lib\\site-packages\\flask\\app.py\", line 2447, in wsgi_app\n",
      "    response = self.full_dispatch_request()\n",
      "  File \"C:\\Users\\admin\\anaconda3\\lib\\site-packages\\flask\\app.py\", line 1952, in full_dispatch_request\n",
      "    rv = self.handle_user_exception(e)\n",
      "  File \"C:\\Users\\admin\\anaconda3\\lib\\site-packages\\flask\\app.py\", line 1821, in handle_user_exception\n",
      "    reraise(exc_type, exc_value, tb)\n",
      "  File \"C:\\Users\\admin\\anaconda3\\lib\\site-packages\\flask\\_compat.py\", line 39, in reraise\n",
      "    raise value\n",
      "  File \"C:\\Users\\admin\\anaconda3\\lib\\site-packages\\flask\\app.py\", line 1950, in full_dispatch_request\n",
      "    rv = self.dispatch_request()\n",
      "  File \"C:\\Users\\admin\\anaconda3\\lib\\site-packages\\flask\\app.py\", line 1936, in dispatch_request\n",
      "    return self.view_functions[rule.endpoint](**req.view_args)\n",
      "  File \"C:\\Users\\admin\\anaconda3\\lib\\site-packages\\dash\\dash.py\", line 1274, in dispatch\n",
      "    ctx.run(\n",
      "  File \"C:\\Users\\admin\\anaconda3\\lib\\site-packages\\dash\\_callback.py\", line 440, in add_context\n",
      "    output_value = func(*func_args, **func_kwargs)  # %% callback invoked %%\n",
      "  File \"C:\\Users\\admin\\AppData\\Local\\Temp\\ipykernel_16924\\2990508254.py\", line 19, in stock_update\n",
      "    df=pdd.DataReader(stock_ticker,'iex',start,end)\n",
      "  File \"C:\\Users\\admin\\anaconda3\\lib\\site-packages\\pandas\\util\\_decorators.py\", line 207, in wrapper\n",
      "    return func(*args, **kwargs)\n",
      "  File \"C:\\Users\\admin\\anaconda3\\lib\\site-packages\\pandas_datareader\\data.py\", line 382, in DataReader\n",
      "    return IEXDailyReader(\n",
      "  File \"C:\\Users\\admin\\anaconda3\\lib\\site-packages\\pandas_datareader\\iex\\daily.py\", line 143, in read\n",
      "    return self._read_one_data(self.url, self._get_params(self.symbols))\n",
      "  File \"C:\\Users\\admin\\anaconda3\\lib\\site-packages\\pandas_datareader\\base.py\", line 113, in _read_one_data\n",
      "    return self._read_lines(out)\n",
      "  File \"C:\\Users\\admin\\anaconda3\\lib\\site-packages\\pandas_datareader\\iex\\daily.py\", line 156, in _read_lines\n",
      "    d = json_data.pop(symbol)[\"chart\"]\n",
      "KeyError: 'g'\n"
     ]
    },
    {
     "name": "stderr",
     "output_type": "stream",
     "text": [
      "127.0.0.1 - - [03/Jan/2023 01:58:23] \"POST /_dash-update-component HTTP/1.1\" 500 -\n"
     ]
    },
    {
     "name": "stdout",
     "output_type": "stream",
     "text": [
      "Exception on /_dash-update-component [POST]\n",
      "Traceback (most recent call last):\n",
      "  File \"C:\\Users\\admin\\anaconda3\\lib\\site-packages\\flask\\app.py\", line 2447, in wsgi_app\n",
      "    response = self.full_dispatch_request()\n",
      "  File \"C:\\Users\\admin\\anaconda3\\lib\\site-packages\\flask\\app.py\", line 1952, in full_dispatch_request\n",
      "    rv = self.handle_user_exception(e)\n",
      "  File \"C:\\Users\\admin\\anaconda3\\lib\\site-packages\\flask\\app.py\", line 1821, in handle_user_exception\n",
      "    reraise(exc_type, exc_value, tb)\n",
      "  File \"C:\\Users\\admin\\anaconda3\\lib\\site-packages\\flask\\_compat.py\", line 39, in reraise\n",
      "    raise value\n",
      "  File \"C:\\Users\\admin\\anaconda3\\lib\\site-packages\\flask\\app.py\", line 1950, in full_dispatch_request\n",
      "    rv = self.dispatch_request()\n",
      "  File \"C:\\Users\\admin\\anaconda3\\lib\\site-packages\\flask\\app.py\", line 1936, in dispatch_request\n",
      "    return self.view_functions[rule.endpoint](**req.view_args)\n",
      "  File \"C:\\Users\\admin\\anaconda3\\lib\\site-packages\\dash\\dash.py\", line 1274, in dispatch\n",
      "    ctx.run(\n",
      "  File \"C:\\Users\\admin\\anaconda3\\lib\\site-packages\\dash\\_callback.py\", line 440, in add_context\n",
      "    output_value = func(*func_args, **func_kwargs)  # %% callback invoked %%\n",
      "  File \"C:\\Users\\admin\\AppData\\Local\\Temp\\ipykernel_16924\\2990508254.py\", line 19, in stock_update\n",
      "    df=pdd.DataReader(stock_ticker,'iex',start,end)\n",
      "  File \"C:\\Users\\admin\\anaconda3\\lib\\site-packages\\pandas\\util\\_decorators.py\", line 207, in wrapper\n",
      "    return func(*args, **kwargs)\n",
      "  File \"C:\\Users\\admin\\anaconda3\\lib\\site-packages\\pandas_datareader\\data.py\", line 382, in DataReader\n",
      "    return IEXDailyReader(\n",
      "  File \"C:\\Users\\admin\\anaconda3\\lib\\site-packages\\pandas_datareader\\iex\\daily.py\", line 143, in read\n",
      "    return self._read_one_data(self.url, self._get_params(self.symbols))\n",
      "  File \"C:\\Users\\admin\\anaconda3\\lib\\site-packages\\pandas_datareader\\base.py\", line 108, in _read_one_data\n",
      "    out = self._read_url_as_StringIO(url, params=params)\n",
      "  File \"C:\\Users\\admin\\anaconda3\\lib\\site-packages\\pandas_datareader\\base.py\", line 119, in _read_url_as_StringIO\n",
      "    response = self._get_response(url, params=params)\n",
      "  File \"C:\\Users\\admin\\anaconda3\\lib\\site-packages\\pandas_datareader\\base.py\", line 181, in _get_response\n",
      "    raise RemoteDataError(msg)\n",
      "pandas_datareader._utils.RemoteDataError: Unable to read URL: https://cloud.iexapis.com/stable/stock/market/batch?symbols=&types=chart&range=max&token=pk_e124697d80704446893c52da182883c8\n",
      "Response Text:\n",
      "b'{\"error\":\"\\\\\"symbols\\\\\" is not allowed to be empty\"}'\n"
     ]
    },
    {
     "name": "stderr",
     "output_type": "stream",
     "text": [
      "127.0.0.1 - - [03/Jan/2023 01:58:24] \"POST /_dash-update-component HTTP/1.1\" 500 -\n"
     ]
    },
    {
     "name": "stdout",
     "output_type": "stream",
     "text": [
      "Exception on /_dash-update-component [POST]\n",
      "Traceback (most recent call last):\n",
      "  File \"C:\\Users\\admin\\anaconda3\\lib\\site-packages\\flask\\app.py\", line 2447, in wsgi_app\n",
      "    response = self.full_dispatch_request()\n",
      "  File \"C:\\Users\\admin\\anaconda3\\lib\\site-packages\\flask\\app.py\", line 1952, in full_dispatch_request\n",
      "    rv = self.handle_user_exception(e)\n",
      "  File \"C:\\Users\\admin\\anaconda3\\lib\\site-packages\\flask\\app.py\", line 1821, in handle_user_exception\n",
      "    reraise(exc_type, exc_value, tb)\n",
      "  File \"C:\\Users\\admin\\anaconda3\\lib\\site-packages\\flask\\_compat.py\", line 39, in reraise\n",
      "    raise value\n",
      "  File \"C:\\Users\\admin\\anaconda3\\lib\\site-packages\\flask\\app.py\", line 1950, in full_dispatch_request\n",
      "    rv = self.dispatch_request()\n",
      "  File \"C:\\Users\\admin\\anaconda3\\lib\\site-packages\\flask\\app.py\", line 1936, in dispatch_request\n",
      "    return self.view_functions[rule.endpoint](**req.view_args)\n",
      "  File \"C:\\Users\\admin\\anaconda3\\lib\\site-packages\\dash\\dash.py\", line 1274, in dispatch\n",
      "    ctx.run(\n",
      "  File \"C:\\Users\\admin\\anaconda3\\lib\\site-packages\\dash\\_callback.py\", line 440, in add_context\n",
      "    output_value = func(*func_args, **func_kwargs)  # %% callback invoked %%\n",
      "  File \"C:\\Users\\admin\\AppData\\Local\\Temp\\ipykernel_16924\\2990508254.py\", line 19, in stock_update\n",
      "    df=pdd.DataReader(stock_ticker,'iex',start,end)\n",
      "  File \"C:\\Users\\admin\\anaconda3\\lib\\site-packages\\pandas\\util\\_decorators.py\", line 207, in wrapper\n",
      "    return func(*args, **kwargs)\n",
      "  File \"C:\\Users\\admin\\anaconda3\\lib\\site-packages\\pandas_datareader\\data.py\", line 382, in DataReader\n",
      "    return IEXDailyReader(\n",
      "  File \"C:\\Users\\admin\\anaconda3\\lib\\site-packages\\pandas_datareader\\iex\\daily.py\", line 143, in read\n",
      "    return self._read_one_data(self.url, self._get_params(self.symbols))\n",
      "  File \"C:\\Users\\admin\\anaconda3\\lib\\site-packages\\pandas_datareader\\base.py\", line 113, in _read_one_data\n",
      "    return self._read_lines(out)\n",
      "  File \"C:\\Users\\admin\\anaconda3\\lib\\site-packages\\pandas_datareader\\iex\\daily.py\", line 158, in _read_lines\n",
      "    df.set_index(\"date\", inplace=True)\n",
      "  File \"C:\\Users\\admin\\anaconda3\\lib\\site-packages\\pandas\\util\\_decorators.py\", line 311, in wrapper\n",
      "    return func(*args, **kwargs)\n",
      "  File \"C:\\Users\\admin\\anaconda3\\lib\\site-packages\\pandas\\core\\frame.py\", line 5494, in set_index\n",
      "    raise KeyError(f\"None of {missing} are in the columns\")\n",
      "KeyError: \"None of ['date'] are in the columns\"\n"
     ]
    },
    {
     "name": "stderr",
     "output_type": "stream",
     "text": [
      "127.0.0.1 - - [03/Jan/2023 01:58:24] \"POST /_dash-update-component HTTP/1.1\" 500 -\n",
      "127.0.0.1 - - [03/Jan/2023 01:58:26] \"POST /_dash-update-component HTTP/1.1\" 200 -\n"
     ]
    },
    {
     "name": "stdout",
     "output_type": "stream",
     "text": [
      "Exception on /_dash-update-component [POST]\n",
      "Traceback (most recent call last):\n",
      "  File \"C:\\Users\\admin\\anaconda3\\lib\\site-packages\\flask\\app.py\", line 2447, in wsgi_app\n",
      "    response = self.full_dispatch_request()\n",
      "  File \"C:\\Users\\admin\\anaconda3\\lib\\site-packages\\flask\\app.py\", line 1952, in full_dispatch_request\n",
      "    rv = self.handle_user_exception(e)\n",
      "  File \"C:\\Users\\admin\\anaconda3\\lib\\site-packages\\flask\\app.py\", line 1821, in handle_user_exception\n",
      "    reraise(exc_type, exc_value, tb)\n",
      "  File \"C:\\Users\\admin\\anaconda3\\lib\\site-packages\\flask\\_compat.py\", line 39, in reraise\n",
      "    raise value\n",
      "  File \"C:\\Users\\admin\\anaconda3\\lib\\site-packages\\flask\\app.py\", line 1950, in full_dispatch_request\n",
      "    rv = self.dispatch_request()\n",
      "  File \"C:\\Users\\admin\\anaconda3\\lib\\site-packages\\flask\\app.py\", line 1936, in dispatch_request\n",
      "    return self.view_functions[rule.endpoint](**req.view_args)\n",
      "  File \"C:\\Users\\admin\\anaconda3\\lib\\site-packages\\dash\\dash.py\", line 1274, in dispatch\n",
      "    ctx.run(\n",
      "  File \"C:\\Users\\admin\\anaconda3\\lib\\site-packages\\dash\\_callback.py\", line 440, in add_context\n",
      "    output_value = func(*func_args, **func_kwargs)  # %% callback invoked %%\n",
      "  File \"C:\\Users\\admin\\AppData\\Local\\Temp\\ipykernel_16924\\2990508254.py\", line 19, in stock_update\n",
      "    df=pdd.DataReader(stock_ticker,'iex',start,end)\n",
      "  File \"C:\\Users\\admin\\anaconda3\\lib\\site-packages\\pandas\\util\\_decorators.py\", line 207, in wrapper\n",
      "    return func(*args, **kwargs)\n",
      "  File \"C:\\Users\\admin\\anaconda3\\lib\\site-packages\\pandas_datareader\\data.py\", line 382, in DataReader\n",
      "    return IEXDailyReader(\n",
      "  File \"C:\\Users\\admin\\anaconda3\\lib\\site-packages\\pandas_datareader\\iex\\daily.py\", line 143, in read\n",
      "    return self._read_one_data(self.url, self._get_params(self.symbols))\n",
      "  File \"C:\\Users\\admin\\anaconda3\\lib\\site-packages\\pandas_datareader\\base.py\", line 113, in _read_one_data\n",
      "    return self._read_lines(out)\n",
      "  File \"C:\\Users\\admin\\anaconda3\\lib\\site-packages\\pandas_datareader\\iex\\daily.py\", line 158, in _read_lines\n",
      "    df.set_index(\"date\", inplace=True)\n",
      "  File \"C:\\Users\\admin\\anaconda3\\lib\\site-packages\\pandas\\util\\_decorators.py\", line 311, in wrapper\n",
      "    return func(*args, **kwargs)\n",
      "  File \"C:\\Users\\admin\\anaconda3\\lib\\site-packages\\pandas\\core\\frame.py\", line 5494, in set_index\n",
      "    raise KeyError(f\"None of {missing} are in the columns\")\n",
      "KeyError: \"None of ['date'] are in the columns\"\n"
     ]
    },
    {
     "name": "stderr",
     "output_type": "stream",
     "text": [
      "127.0.0.1 - - [03/Jan/2023 01:58:27] \"POST /_dash-update-component HTTP/1.1\" 500 -\n"
     ]
    },
    {
     "name": "stdout",
     "output_type": "stream",
     "text": [
      "Exception on /_dash-update-component [POST]\n",
      "Traceback (most recent call last):\n",
      "  File \"C:\\Users\\admin\\anaconda3\\lib\\site-packages\\flask\\app.py\", line 2447, in wsgi_app\n",
      "    response = self.full_dispatch_request()\n",
      "  File \"C:\\Users\\admin\\anaconda3\\lib\\site-packages\\flask\\app.py\", line 1952, in full_dispatch_request\n",
      "    rv = self.handle_user_exception(e)\n",
      "  File \"C:\\Users\\admin\\anaconda3\\lib\\site-packages\\flask\\app.py\", line 1821, in handle_user_exception\n",
      "    reraise(exc_type, exc_value, tb)\n",
      "  File \"C:\\Users\\admin\\anaconda3\\lib\\site-packages\\flask\\_compat.py\", line 39, in reraise\n",
      "    raise value\n",
      "  File \"C:\\Users\\admin\\anaconda3\\lib\\site-packages\\flask\\app.py\", line 1950, in full_dispatch_request\n",
      "    rv = self.dispatch_request()\n",
      "  File \"C:\\Users\\admin\\anaconda3\\lib\\site-packages\\flask\\app.py\", line 1936, in dispatch_request\n",
      "    return self.view_functions[rule.endpoint](**req.view_args)\n",
      "  File \"C:\\Users\\admin\\anaconda3\\lib\\site-packages\\dash\\dash.py\", line 1274, in dispatch\n",
      "    ctx.run(\n",
      "  File \"C:\\Users\\admin\\anaconda3\\lib\\site-packages\\dash\\_callback.py\", line 440, in add_context\n",
      "    output_value = func(*func_args, **func_kwargs)  # %% callback invoked %%\n",
      "  File \"C:\\Users\\admin\\AppData\\Local\\Temp\\ipykernel_16924\\2990508254.py\", line 19, in stock_update\n",
      "    df=pdd.DataReader(stock_ticker,'iex',start,end)\n",
      "  File \"C:\\Users\\admin\\anaconda3\\lib\\site-packages\\pandas\\util\\_decorators.py\", line 207, in wrapper\n",
      "    return func(*args, **kwargs)\n",
      "  File \"C:\\Users\\admin\\anaconda3\\lib\\site-packages\\pandas_datareader\\data.py\", line 382, in DataReader\n",
      "    return IEXDailyReader(\n",
      "  File \"C:\\Users\\admin\\anaconda3\\lib\\site-packages\\pandas_datareader\\iex\\daily.py\", line 143, in read\n",
      "    return self._read_one_data(self.url, self._get_params(self.symbols))\n",
      "  File \"C:\\Users\\admin\\anaconda3\\lib\\site-packages\\pandas_datareader\\base.py\", line 113, in _read_one_data\n",
      "    return self._read_lines(out)\n",
      "  File \"C:\\Users\\admin\\anaconda3\\lib\\site-packages\\pandas_datareader\\iex\\daily.py\", line 158, in _read_lines\n",
      "    df.set_index(\"date\", inplace=True)\n",
      "  File \"C:\\Users\\admin\\anaconda3\\lib\\site-packages\\pandas\\util\\_decorators.py\", line 311, in wrapper\n",
      "    return func(*args, **kwargs)\n",
      "  File \"C:\\Users\\admin\\anaconda3\\lib\\site-packages\\pandas\\core\\frame.py\", line 5494, in set_index\n",
      "    raise KeyError(f\"None of {missing} are in the columns\")\n",
      "KeyError: \"None of ['date'] are in the columns\"\n"
     ]
    },
    {
     "name": "stderr",
     "output_type": "stream",
     "text": [
      "127.0.0.1 - - [03/Jan/2023 01:58:28] \"POST /_dash-update-component HTTP/1.1\" 500 -\n",
      "127.0.0.1 - - [03/Jan/2023 01:58:29] \"POST /_dash-update-component HTTP/1.1\" 200 -\n",
      "127.0.0.1 - - [03/Jan/2023 01:58:29] \"POST /_dash-update-component HTTP/1.1\" 200 -\n"
     ]
    },
    {
     "name": "stdout",
     "output_type": "stream",
     "text": [
      "Exception on /_dash-update-component [POST]\n",
      "Traceback (most recent call last):\n",
      "  File \"C:\\Users\\admin\\anaconda3\\lib\\site-packages\\flask\\app.py\", line 2447, in wsgi_app\n",
      "    response = self.full_dispatch_request()\n",
      "  File \"C:\\Users\\admin\\anaconda3\\lib\\site-packages\\flask\\app.py\", line 1952, in full_dispatch_request\n",
      "    rv = self.handle_user_exception(e)\n",
      "  File \"C:\\Users\\admin\\anaconda3\\lib\\site-packages\\flask\\app.py\", line 1821, in handle_user_exception\n",
      "    reraise(exc_type, exc_value, tb)\n",
      "  File \"C:\\Users\\admin\\anaconda3\\lib\\site-packages\\flask\\_compat.py\", line 39, in reraise\n",
      "    raise value\n",
      "  File \"C:\\Users\\admin\\anaconda3\\lib\\site-packages\\flask\\app.py\", line 1950, in full_dispatch_request\n",
      "    rv = self.dispatch_request()\n",
      "  File \"C:\\Users\\admin\\anaconda3\\lib\\site-packages\\flask\\app.py\", line 1936, in dispatch_request\n",
      "    return self.view_functions[rule.endpoint](**req.view_args)\n",
      "  File \"C:\\Users\\admin\\anaconda3\\lib\\site-packages\\dash\\dash.py\", line 1274, in dispatch\n",
      "    ctx.run(\n",
      "  File \"C:\\Users\\admin\\anaconda3\\lib\\site-packages\\dash\\_callback.py\", line 440, in add_context\n",
      "    output_value = func(*func_args, **func_kwargs)  # %% callback invoked %%\n",
      "  File \"C:\\Users\\admin\\AppData\\Local\\Temp\\ipykernel_16924\\2990508254.py\", line 19, in stock_update\n",
      "    df=pdd.DataReader(stock_ticker,'iex',start,end)\n",
      "  File \"C:\\Users\\admin\\anaconda3\\lib\\site-packages\\pandas\\util\\_decorators.py\", line 207, in wrapper\n",
      "    return func(*args, **kwargs)\n",
      "  File \"C:\\Users\\admin\\anaconda3\\lib\\site-packages\\pandas_datareader\\data.py\", line 382, in DataReader\n",
      "    return IEXDailyReader(\n",
      "  File \"C:\\Users\\admin\\anaconda3\\lib\\site-packages\\pandas_datareader\\iex\\daily.py\", line 143, in read\n",
      "    return self._read_one_data(self.url, self._get_params(self.symbols))\n",
      "  File \"C:\\Users\\admin\\anaconda3\\lib\\site-packages\\pandas_datareader\\base.py\", line 108, in _read_one_data\n",
      "    out = self._read_url_as_StringIO(url, params=params)\n",
      "  File \"C:\\Users\\admin\\anaconda3\\lib\\site-packages\\pandas_datareader\\base.py\", line 119, in _read_url_as_StringIO\n",
      "    response = self._get_response(url, params=params)\n",
      "  File \"C:\\Users\\admin\\anaconda3\\lib\\site-packages\\pandas_datareader\\base.py\", line 181, in _get_response\n",
      "    raise RemoteDataError(msg)\n",
      "pandas_datareader._utils.RemoteDataError: Unable to read URL: https://cloud.iexapis.com/stable/stock/market/batch?symbols=GOO&types=chart&range=max&token=pk_e124697d80704446893c52da182883c8\n"
     ]
    },
    {
     "name": "stderr",
     "output_type": "stream",
     "text": [
      "127.0.0.1 - - [03/Jan/2023 01:58:30] \"POST /_dash-update-component HTTP/1.1\" 500 -\n",
      "127.0.0.1 - - [03/Jan/2023 01:58:30] \"POST /_dash-update-component HTTP/1.1\" 200 -\n"
     ]
    },
    {
     "name": "stdout",
     "output_type": "stream",
     "text": [
      "Exception on /_dash-update-component [POST]\n",
      "Traceback (most recent call last):\n",
      "  File \"C:\\Users\\admin\\anaconda3\\lib\\site-packages\\flask\\app.py\", line 2447, in wsgi_app\n",
      "    response = self.full_dispatch_request()\n",
      "  File \"C:\\Users\\admin\\anaconda3\\lib\\site-packages\\flask\\app.py\", line 1952, in full_dispatch_request\n",
      "    rv = self.handle_user_exception(e)\n",
      "  File \"C:\\Users\\admin\\anaconda3\\lib\\site-packages\\flask\\app.py\", line 1821, in handle_user_exception\n",
      "    reraise(exc_type, exc_value, tb)\n",
      "  File \"C:\\Users\\admin\\anaconda3\\lib\\site-packages\\flask\\_compat.py\", line 39, in reraise\n",
      "    raise value\n",
      "  File \"C:\\Users\\admin\\anaconda3\\lib\\site-packages\\flask\\app.py\", line 1950, in full_dispatch_request\n",
      "    rv = self.dispatch_request()\n",
      "  File \"C:\\Users\\admin\\anaconda3\\lib\\site-packages\\flask\\app.py\", line 1936, in dispatch_request\n",
      "    return self.view_functions[rule.endpoint](**req.view_args)\n",
      "  File \"C:\\Users\\admin\\anaconda3\\lib\\site-packages\\dash\\dash.py\", line 1274, in dispatch\n",
      "    ctx.run(\n",
      "  File \"C:\\Users\\admin\\anaconda3\\lib\\site-packages\\dash\\_callback.py\", line 440, in add_context\n",
      "    output_value = func(*func_args, **func_kwargs)  # %% callback invoked %%\n",
      "  File \"C:\\Users\\admin\\AppData\\Local\\Temp\\ipykernel_16924\\2990508254.py\", line 19, in stock_update\n",
      "    df=pdd.DataReader(stock_ticker,'iex',start,end)\n",
      "  File \"C:\\Users\\admin\\anaconda3\\lib\\site-packages\\pandas\\util\\_decorators.py\", line 207, in wrapper\n",
      "    return func(*args, **kwargs)\n",
      "  File \"C:\\Users\\admin\\anaconda3\\lib\\site-packages\\pandas_datareader\\data.py\", line 382, in DataReader\n",
      "    return IEXDailyReader(\n",
      "  File \"C:\\Users\\admin\\anaconda3\\lib\\site-packages\\pandas_datareader\\iex\\daily.py\", line 143, in read\n",
      "    return self._read_one_data(self.url, self._get_params(self.symbols))\n",
      "  File \"C:\\Users\\admin\\anaconda3\\lib\\site-packages\\pandas_datareader\\base.py\", line 108, in _read_one_data\n",
      "    out = self._read_url_as_StringIO(url, params=params)\n",
      "  File \"C:\\Users\\admin\\anaconda3\\lib\\site-packages\\pandas_datareader\\base.py\", line 119, in _read_url_as_StringIO\n",
      "    response = self._get_response(url, params=params)\n",
      "  File \"C:\\Users\\admin\\anaconda3\\lib\\site-packages\\pandas_datareader\\base.py\", line 181, in _get_response\n",
      "    raise RemoteDataError(msg)\n",
      "pandas_datareader._utils.RemoteDataError: Unable to read URL: https://cloud.iexapis.com/stable/stock/market/batch?symbols=GOOGLE&types=chart&range=max&token=pk_e124697d80704446893c52da182883c8\n"
     ]
    },
    {
     "name": "stderr",
     "output_type": "stream",
     "text": [
      "127.0.0.1 - - [03/Jan/2023 01:58:31] \"POST /_dash-update-component HTTP/1.1\" 500 -\n",
      "127.0.0.1 - - [03/Jan/2023 01:58:31] \"POST /_dash-update-component HTTP/1.1\" 200 -\n"
     ]
    },
    {
     "name": "stdout",
     "output_type": "stream",
     "text": [
      "Exception on /_dash-update-component [POST]\n",
      "Traceback (most recent call last):\n",
      "  File \"C:\\Users\\admin\\anaconda3\\lib\\site-packages\\flask\\app.py\", line 2447, in wsgi_app\n",
      "    response = self.full_dispatch_request()\n",
      "  File \"C:\\Users\\admin\\anaconda3\\lib\\site-packages\\flask\\app.py\", line 1952, in full_dispatch_request\n",
      "    rv = self.handle_user_exception(e)\n",
      "  File \"C:\\Users\\admin\\anaconda3\\lib\\site-packages\\flask\\app.py\", line 1821, in handle_user_exception\n",
      "    reraise(exc_type, exc_value, tb)\n",
      "  File \"C:\\Users\\admin\\anaconda3\\lib\\site-packages\\flask\\_compat.py\", line 39, in reraise\n",
      "    raise value\n",
      "  File \"C:\\Users\\admin\\anaconda3\\lib\\site-packages\\flask\\app.py\", line 1950, in full_dispatch_request\n",
      "    rv = self.dispatch_request()\n",
      "  File \"C:\\Users\\admin\\anaconda3\\lib\\site-packages\\flask\\app.py\", line 1936, in dispatch_request\n",
      "    return self.view_functions[rule.endpoint](**req.view_args)\n",
      "  File \"C:\\Users\\admin\\anaconda3\\lib\\site-packages\\dash\\dash.py\", line 1274, in dispatch\n",
      "    ctx.run(\n",
      "  File \"C:\\Users\\admin\\anaconda3\\lib\\site-packages\\dash\\_callback.py\", line 440, in add_context\n",
      "    output_value = func(*func_args, **func_kwargs)  # %% callback invoked %%\n",
      "  File \"C:\\Users\\admin\\AppData\\Local\\Temp\\ipykernel_16924\\2990508254.py\", line 19, in stock_update\n",
      "    df=pdd.DataReader(stock_ticker,'iex',start,end)\n",
      "  File \"C:\\Users\\admin\\anaconda3\\lib\\site-packages\\pandas\\util\\_decorators.py\", line 207, in wrapper\n",
      "    return func(*args, **kwargs)\n",
      "  File \"C:\\Users\\admin\\anaconda3\\lib\\site-packages\\pandas_datareader\\data.py\", line 382, in DataReader\n",
      "    return IEXDailyReader(\n",
      "  File \"C:\\Users\\admin\\anaconda3\\lib\\site-packages\\pandas_datareader\\iex\\daily.py\", line 143, in read\n",
      "    return self._read_one_data(self.url, self._get_params(self.symbols))\n",
      "  File \"C:\\Users\\admin\\anaconda3\\lib\\site-packages\\pandas_datareader\\base.py\", line 108, in _read_one_data\n",
      "    out = self._read_url_as_StringIO(url, params=params)\n",
      "  File \"C:\\Users\\admin\\anaconda3\\lib\\site-packages\\pandas_datareader\\base.py\", line 119, in _read_url_as_StringIO\n",
      "    response = self._get_response(url, params=params)\n",
      "  File \"C:\\Users\\admin\\anaconda3\\lib\\site-packages\\pandas_datareader\\base.py\", line 181, in _get_response\n",
      "    raise RemoteDataError(msg)\n",
      "pandas_datareader._utils.RemoteDataError: Unable to read URL: https://cloud.iexapis.com/stable/stock/market/batch?symbols=GOO&types=chart&range=max&token=pk_e124697d80704446893c52da182883c8\n"
     ]
    },
    {
     "name": "stderr",
     "output_type": "stream",
     "text": [
      "127.0.0.1 - - [03/Jan/2023 01:58:34] \"POST /_dash-update-component HTTP/1.1\" 500 -\n"
     ]
    },
    {
     "name": "stdout",
     "output_type": "stream",
     "text": [
      "Exception on /_dash-update-component [POST]\n",
      "Traceback (most recent call last):\n",
      "  File \"C:\\Users\\admin\\anaconda3\\lib\\site-packages\\flask\\app.py\", line 2447, in wsgi_app\n",
      "    response = self.full_dispatch_request()\n",
      "  File \"C:\\Users\\admin\\anaconda3\\lib\\site-packages\\flask\\app.py\", line 1952, in full_dispatch_request\n",
      "    rv = self.handle_user_exception(e)\n",
      "  File \"C:\\Users\\admin\\anaconda3\\lib\\site-packages\\flask\\app.py\", line 1821, in handle_user_exception\n",
      "    reraise(exc_type, exc_value, tb)\n",
      "  File \"C:\\Users\\admin\\anaconda3\\lib\\site-packages\\flask\\_compat.py\", line 39, in reraise\n",
      "    raise value\n",
      "  File \"C:\\Users\\admin\\anaconda3\\lib\\site-packages\\flask\\app.py\", line 1950, in full_dispatch_request\n",
      "    rv = self.dispatch_request()\n",
      "  File \"C:\\Users\\admin\\anaconda3\\lib\\site-packages\\flask\\app.py\", line 1936, in dispatch_request\n",
      "    return self.view_functions[rule.endpoint](**req.view_args)\n",
      "  File \"C:\\Users\\admin\\anaconda3\\lib\\site-packages\\dash\\dash.py\", line 1274, in dispatch\n",
      "    ctx.run(\n",
      "  File \"C:\\Users\\admin\\anaconda3\\lib\\site-packages\\dash\\_callback.py\", line 440, in add_context\n",
      "    output_value = func(*func_args, **func_kwargs)  # %% callback invoked %%\n",
      "  File \"C:\\Users\\admin\\AppData\\Local\\Temp\\ipykernel_16924\\2990508254.py\", line 19, in stock_update\n",
      "    df=pdd.DataReader(stock_ticker,'iex',start,end)\n",
      "  File \"C:\\Users\\admin\\anaconda3\\lib\\site-packages\\pandas\\util\\_decorators.py\", line 207, in wrapper\n",
      "    return func(*args, **kwargs)\n",
      "  File \"C:\\Users\\admin\\anaconda3\\lib\\site-packages\\pandas_datareader\\data.py\", line 382, in DataReader\n",
      "    return IEXDailyReader(\n",
      "  File \"C:\\Users\\admin\\anaconda3\\lib\\site-packages\\pandas_datareader\\iex\\daily.py\", line 143, in read\n",
      "    return self._read_one_data(self.url, self._get_params(self.symbols))\n",
      "  File \"C:\\Users\\admin\\anaconda3\\lib\\site-packages\\pandas_datareader\\base.py\", line 108, in _read_one_data\n",
      "    out = self._read_url_as_StringIO(url, params=params)\n",
      "  File \"C:\\Users\\admin\\anaconda3\\lib\\site-packages\\pandas_datareader\\base.py\", line 119, in _read_url_as_StringIO\n",
      "    response = self._get_response(url, params=params)\n",
      "  File \"C:\\Users\\admin\\anaconda3\\lib\\site-packages\\pandas_datareader\\base.py\", line 181, in _get_response\n",
      "    raise RemoteDataError(msg)\n",
      "pandas_datareader._utils.RemoteDataError: Unable to read URL: https://cloud.iexapis.com/stable/stock/market/batch?symbols=&types=chart&range=max&token=pk_e124697d80704446893c52da182883c8\n",
      "Response Text:\n",
      "b'{\"error\":\"\\\\\"symbols\\\\\" is not allowed to be empty\"}'\n"
     ]
    },
    {
     "name": "stderr",
     "output_type": "stream",
     "text": [
      "127.0.0.1 - - [03/Jan/2023 01:58:35] \"POST /_dash-update-component HTTP/1.1\" 500 -\n",
      "127.0.0.1 - - [03/Jan/2023 01:58:35] \"POST /_dash-update-component HTTP/1.1\" 200 -\n",
      "127.0.0.1 - - [03/Jan/2023 01:58:36] \"POST /_dash-update-component HTTP/1.1\" 200 -\n",
      "127.0.0.1 - - [03/Jan/2023 01:58:36] \"POST /_dash-update-component HTTP/1.1\" 200 -\n",
      "127.0.0.1 - - [03/Jan/2023 01:58:36] \"POST /_dash-update-component HTTP/1.1\" 200 -\n"
     ]
    },
    {
     "name": "stdout",
     "output_type": "stream",
     "text": [
      "Exception on /_dash-update-component [POST]\n",
      "Traceback (most recent call last):\n",
      "  File \"C:\\Users\\admin\\anaconda3\\lib\\site-packages\\flask\\app.py\", line 2447, in wsgi_app\n",
      "    response = self.full_dispatch_request()\n",
      "  File \"C:\\Users\\admin\\anaconda3\\lib\\site-packages\\flask\\app.py\", line 1952, in full_dispatch_request\n",
      "    rv = self.handle_user_exception(e)\n",
      "  File \"C:\\Users\\admin\\anaconda3\\lib\\site-packages\\flask\\app.py\", line 1821, in handle_user_exception\n",
      "    reraise(exc_type, exc_value, tb)\n",
      "  File \"C:\\Users\\admin\\anaconda3\\lib\\site-packages\\flask\\_compat.py\", line 39, in reraise\n",
      "    raise value\n",
      "  File \"C:\\Users\\admin\\anaconda3\\lib\\site-packages\\flask\\app.py\", line 1950, in full_dispatch_request\n",
      "    rv = self.dispatch_request()\n",
      "  File \"C:\\Users\\admin\\anaconda3\\lib\\site-packages\\flask\\app.py\", line 1936, in dispatch_request\n",
      "    return self.view_functions[rule.endpoint](**req.view_args)\n",
      "  File \"C:\\Users\\admin\\anaconda3\\lib\\site-packages\\dash\\dash.py\", line 1274, in dispatch\n",
      "    ctx.run(\n",
      "  File \"C:\\Users\\admin\\anaconda3\\lib\\site-packages\\dash\\_callback.py\", line 440, in add_context\n",
      "    output_value = func(*func_args, **func_kwargs)  # %% callback invoked %%\n",
      "  File \"C:\\Users\\admin\\AppData\\Local\\Temp\\ipykernel_16924\\2990508254.py\", line 19, in stock_update\n",
      "    df=pdd.DataReader(stock_ticker,'iex',start,end)\n",
      "  File \"C:\\Users\\admin\\anaconda3\\lib\\site-packages\\pandas\\util\\_decorators.py\", line 207, in wrapper\n",
      "    return func(*args, **kwargs)\n",
      "  File \"C:\\Users\\admin\\anaconda3\\lib\\site-packages\\pandas_datareader\\data.py\", line 382, in DataReader\n",
      "    return IEXDailyReader(\n",
      "  File \"C:\\Users\\admin\\anaconda3\\lib\\site-packages\\pandas_datareader\\iex\\daily.py\", line 143, in read\n",
      "    return self._read_one_data(self.url, self._get_params(self.symbols))\n",
      "  File \"C:\\Users\\admin\\anaconda3\\lib\\site-packages\\pandas_datareader\\base.py\", line 113, in _read_one_data\n",
      "    return self._read_lines(out)\n",
      "  File \"C:\\Users\\admin\\anaconda3\\lib\\site-packages\\pandas_datareader\\iex\\daily.py\", line 158, in _read_lines\n",
      "    df.set_index(\"date\", inplace=True)\n",
      "  File \"C:\\Users\\admin\\anaconda3\\lib\\site-packages\\pandas\\util\\_decorators.py\", line 311, in wrapper\n",
      "    return func(*args, **kwargs)\n",
      "  File \"C:\\Users\\admin\\anaconda3\\lib\\site-packages\\pandas\\core\\frame.py\", line 5494, in set_index\n",
      "    raise KeyError(f\"None of {missing} are in the columns\")\n",
      "KeyError: \"None of ['date'] are in the columns\"\n"
     ]
    },
    {
     "name": "stderr",
     "output_type": "stream",
     "text": [
      "127.0.0.1 - - [03/Jan/2023 01:58:56] \"POST /_dash-update-component HTTP/1.1\" 500 -\n",
      "127.0.0.1 - - [03/Jan/2023 01:58:58] \"POST /_dash-update-component HTTP/1.1\" 200 -\n",
      "127.0.0.1 - - [03/Jan/2023 01:58:58] \"POST /_dash-update-component HTTP/1.1\" 200 -\n",
      "127.0.0.1 - - [03/Jan/2023 01:58:59] \"POST /_dash-update-component HTTP/1.1\" 200 -\n",
      "127.0.0.1 - - [03/Jan/2023 01:58:59] \"POST /_dash-update-component HTTP/1.1\" 200 -\n"
     ]
    },
    {
     "name": "stdout",
     "output_type": "stream",
     "text": [
      "Exception on /_dash-update-component [POST]\n",
      "Traceback (most recent call last):\n",
      "  File \"C:\\Users\\admin\\anaconda3\\lib\\site-packages\\flask\\app.py\", line 2447, in wsgi_app\n",
      "    response = self.full_dispatch_request()\n",
      "  File \"C:\\Users\\admin\\anaconda3\\lib\\site-packages\\flask\\app.py\", line 1952, in full_dispatch_request\n",
      "    rv = self.handle_user_exception(e)\n",
      "  File \"C:\\Users\\admin\\anaconda3\\lib\\site-packages\\flask\\app.py\", line 1821, in handle_user_exception\n",
      "    reraise(exc_type, exc_value, tb)\n",
      "  File \"C:\\Users\\admin\\anaconda3\\lib\\site-packages\\flask\\_compat.py\", line 39, in reraise\n",
      "    raise value\n",
      "  File \"C:\\Users\\admin\\anaconda3\\lib\\site-packages\\flask\\app.py\", line 1950, in full_dispatch_request\n",
      "    rv = self.dispatch_request()\n",
      "  File \"C:\\Users\\admin\\anaconda3\\lib\\site-packages\\flask\\app.py\", line 1936, in dispatch_request\n",
      "    return self.view_functions[rule.endpoint](**req.view_args)\n",
      "  File \"C:\\Users\\admin\\anaconda3\\lib\\site-packages\\dash\\dash.py\", line 1274, in dispatch\n",
      "    ctx.run(\n",
      "  File \"C:\\Users\\admin\\anaconda3\\lib\\site-packages\\dash\\_callback.py\", line 440, in add_context\n",
      "    output_value = func(*func_args, **func_kwargs)  # %% callback invoked %%\n",
      "  File \"C:\\Users\\admin\\AppData\\Local\\Temp\\ipykernel_16924\\2990508254.py\", line 19, in stock_update\n",
      "    df=pdd.DataReader(stock_ticker,'iex',start,end)\n",
      "  File \"C:\\Users\\admin\\anaconda3\\lib\\site-packages\\pandas\\util\\_decorators.py\", line 207, in wrapper\n",
      "    return func(*args, **kwargs)\n",
      "  File \"C:\\Users\\admin\\anaconda3\\lib\\site-packages\\pandas_datareader\\data.py\", line 382, in DataReader\n",
      "    return IEXDailyReader(\n",
      "  File \"C:\\Users\\admin\\anaconda3\\lib\\site-packages\\pandas_datareader\\iex\\daily.py\", line 143, in read\n",
      "    return self._read_one_data(self.url, self._get_params(self.symbols))\n",
      "  File \"C:\\Users\\admin\\anaconda3\\lib\\site-packages\\pandas_datareader\\base.py\", line 108, in _read_one_data\n",
      "    out = self._read_url_as_StringIO(url, params=params)\n",
      "  File \"C:\\Users\\admin\\anaconda3\\lib\\site-packages\\pandas_datareader\\base.py\", line 119, in _read_url_as_StringIO\n",
      "    response = self._get_response(url, params=params)\n",
      "  File \"C:\\Users\\admin\\anaconda3\\lib\\site-packages\\pandas_datareader\\base.py\", line 181, in _get_response\n",
      "    raise RemoteDataError(msg)\n",
      "pandas_datareader._utils.RemoteDataError: Unable to read URL: https://cloud.iexapis.com/stable/stock/market/batch?symbols=GOO&types=chart&range=max&token=pk_e124697d80704446893c52da182883c8\n"
     ]
    },
    {
     "name": "stderr",
     "output_type": "stream",
     "text": [
      "127.0.0.1 - - [03/Jan/2023 01:59:00] \"POST /_dash-update-component HTTP/1.1\" 500 -\n"
     ]
    },
    {
     "name": "stdout",
     "output_type": "stream",
     "text": [
      "Exception on /_dash-update-component [POST]\n",
      "Traceback (most recent call last):\n",
      "  File \"C:\\Users\\admin\\anaconda3\\lib\\site-packages\\flask\\app.py\", line 2447, in wsgi_app\n",
      "    response = self.full_dispatch_request()\n",
      "  File \"C:\\Users\\admin\\anaconda3\\lib\\site-packages\\flask\\app.py\", line 1952, in full_dispatch_request\n",
      "    rv = self.handle_user_exception(e)\n",
      "  File \"C:\\Users\\admin\\anaconda3\\lib\\site-packages\\flask\\app.py\", line 1821, in handle_user_exception\n",
      "    reraise(exc_type, exc_value, tb)\n",
      "  File \"C:\\Users\\admin\\anaconda3\\lib\\site-packages\\flask\\_compat.py\", line 39, in reraise\n",
      "    raise value\n",
      "  File \"C:\\Users\\admin\\anaconda3\\lib\\site-packages\\flask\\app.py\", line 1950, in full_dispatch_request\n",
      "    rv = self.dispatch_request()\n",
      "  File \"C:\\Users\\admin\\anaconda3\\lib\\site-packages\\flask\\app.py\", line 1936, in dispatch_request\n",
      "    return self.view_functions[rule.endpoint](**req.view_args)\n",
      "  File \"C:\\Users\\admin\\anaconda3\\lib\\site-packages\\dash\\dash.py\", line 1274, in dispatch\n",
      "    ctx.run(\n",
      "  File \"C:\\Users\\admin\\anaconda3\\lib\\site-packages\\dash\\_callback.py\", line 440, in add_context\n",
      "    output_value = func(*func_args, **func_kwargs)  # %% callback invoked %%\n",
      "  File \"C:\\Users\\admin\\AppData\\Local\\Temp\\ipykernel_16924\\2990508254.py\", line 19, in stock_update\n",
      "    df=pdd.DataReader(stock_ticker,'iex',start,end)\n",
      "  File \"C:\\Users\\admin\\anaconda3\\lib\\site-packages\\pandas\\util\\_decorators.py\", line 207, in wrapper\n",
      "    return func(*args, **kwargs)\n",
      "  File \"C:\\Users\\admin\\anaconda3\\lib\\site-packages\\pandas_datareader\\data.py\", line 382, in DataReader\n",
      "    return IEXDailyReader(\n",
      "  File \"C:\\Users\\admin\\anaconda3\\lib\\site-packages\\pandas_datareader\\iex\\daily.py\", line 143, in read\n",
      "    return self._read_one_data(self.url, self._get_params(self.symbols))\n",
      "  File \"C:\\Users\\admin\\anaconda3\\lib\\site-packages\\pandas_datareader\\base.py\", line 113, in _read_one_data\n",
      "    return self._read_lines(out)\n",
      "  File \"C:\\Users\\admin\\anaconda3\\lib\\site-packages\\pandas_datareader\\iex\\daily.py\", line 156, in _read_lines\n",
      "    d = json_data.pop(symbol)[\"chart\"]\n",
      "KeyError: 'n'\n"
     ]
    },
    {
     "name": "stderr",
     "output_type": "stream",
     "text": [
      "127.0.0.1 - - [03/Jan/2023 02:04:02] \"POST /_dash-update-component HTTP/1.1\" 500 -\n"
     ]
    },
    {
     "name": "stdout",
     "output_type": "stream",
     "text": [
      "Exception on /_dash-update-component [POST]\n",
      "Traceback (most recent call last):\n",
      "  File \"C:\\Users\\admin\\anaconda3\\lib\\site-packages\\flask\\app.py\", line 2447, in wsgi_app\n",
      "    response = self.full_dispatch_request()\n",
      "  File \"C:\\Users\\admin\\anaconda3\\lib\\site-packages\\flask\\app.py\", line 1952, in full_dispatch_request\n",
      "    rv = self.handle_user_exception(e)\n",
      "  File \"C:\\Users\\admin\\anaconda3\\lib\\site-packages\\flask\\app.py\", line 1821, in handle_user_exception\n",
      "    reraise(exc_type, exc_value, tb)\n",
      "  File \"C:\\Users\\admin\\anaconda3\\lib\\site-packages\\flask\\_compat.py\", line 39, in reraise\n",
      "    raise value\n",
      "  File \"C:\\Users\\admin\\anaconda3\\lib\\site-packages\\flask\\app.py\", line 1950, in full_dispatch_request\n",
      "    rv = self.dispatch_request()\n",
      "  File \"C:\\Users\\admin\\anaconda3\\lib\\site-packages\\flask\\app.py\", line 1936, in dispatch_request\n",
      "    return self.view_functions[rule.endpoint](**req.view_args)\n",
      "  File \"C:\\Users\\admin\\anaconda3\\lib\\site-packages\\dash\\dash.py\", line 1274, in dispatch\n",
      "    ctx.run(\n",
      "  File \"C:\\Users\\admin\\anaconda3\\lib\\site-packages\\dash\\_callback.py\", line 440, in add_context\n",
      "    output_value = func(*func_args, **func_kwargs)  # %% callback invoked %%\n",
      "  File \"C:\\Users\\admin\\AppData\\Local\\Temp\\ipykernel_16924\\2990508254.py\", line 19, in stock_update\n",
      "    df=pdd.DataReader(stock_ticker,'iex',start,end)\n",
      "  File \"C:\\Users\\admin\\anaconda3\\lib\\site-packages\\pandas\\util\\_decorators.py\", line 207, in wrapper\n",
      "    return func(*args, **kwargs)\n",
      "  File \"C:\\Users\\admin\\anaconda3\\lib\\site-packages\\pandas_datareader\\data.py\", line 382, in DataReader\n",
      "    return IEXDailyReader(\n",
      "  File \"C:\\Users\\admin\\anaconda3\\lib\\site-packages\\pandas_datareader\\iex\\daily.py\", line 143, in read\n",
      "    return self._read_one_data(self.url, self._get_params(self.symbols))\n",
      "  File \"C:\\Users\\admin\\anaconda3\\lib\\site-packages\\pandas_datareader\\base.py\", line 108, in _read_one_data\n",
      "    out = self._read_url_as_StringIO(url, params=params)\n",
      "  File \"C:\\Users\\admin\\anaconda3\\lib\\site-packages\\pandas_datareader\\base.py\", line 119, in _read_url_as_StringIO\n",
      "    response = self._get_response(url, params=params)\n",
      "  File \"C:\\Users\\admin\\anaconda3\\lib\\site-packages\\pandas_datareader\\base.py\", line 181, in _get_response\n",
      "    raise RemoteDataError(msg)\n",
      "pandas_datareader._utils.RemoteDataError: Unable to read URL: https://cloud.iexapis.com/stable/stock/market/batch?symbols=GOO&types=chart&range=max&token=pk_e124697d80704446893c52da182883c8\n"
     ]
    },
    {
     "name": "stderr",
     "output_type": "stream",
     "text": [
      "127.0.0.1 - - [03/Jan/2023 02:04:02] \"POST /_dash-update-component HTTP/1.1\" 500 -\n",
      "127.0.0.1 - - [03/Jan/2023 02:04:02] \"POST /_dash-update-component HTTP/1.1\" 200 -\n"
     ]
    },
    {
     "name": "stdout",
     "output_type": "stream",
     "text": [
      "Exception on /_dash-update-component [POST]\n",
      "Traceback (most recent call last):\n",
      "  File \"C:\\Users\\admin\\anaconda3\\lib\\site-packages\\flask\\app.py\", line 2447, in wsgi_app\n",
      "    response = self.full_dispatch_request()\n",
      "  File \"C:\\Users\\admin\\anaconda3\\lib\\site-packages\\flask\\app.py\", line 1952, in full_dispatch_request\n",
      "    rv = self.handle_user_exception(e)\n",
      "  File \"C:\\Users\\admin\\anaconda3\\lib\\site-packages\\flask\\app.py\", line 1821, in handle_user_exception\n",
      "    reraise(exc_type, exc_value, tb)\n",
      "  File \"C:\\Users\\admin\\anaconda3\\lib\\site-packages\\flask\\_compat.py\", line 39, in reraise\n",
      "    raise value\n",
      "  File \"C:\\Users\\admin\\anaconda3\\lib\\site-packages\\flask\\app.py\", line 1950, in full_dispatch_request\n",
      "    rv = self.dispatch_request()\n",
      "  File \"C:\\Users\\admin\\anaconda3\\lib\\site-packages\\flask\\app.py\", line 1936, in dispatch_request\n",
      "    return self.view_functions[rule.endpoint](**req.view_args)\n",
      "  File \"C:\\Users\\admin\\anaconda3\\lib\\site-packages\\dash\\dash.py\", line 1274, in dispatch\n",
      "    ctx.run(\n",
      "  File \"C:\\Users\\admin\\anaconda3\\lib\\site-packages\\dash\\_callback.py\", line 440, in add_context\n",
      "    output_value = func(*func_args, **func_kwargs)  # %% callback invoked %%\n",
      "  File \"C:\\Users\\admin\\AppData\\Local\\Temp\\ipykernel_16924\\2990508254.py\", line 19, in stock_update\n",
      "    df=pdd.DataReader(stock_ticker,'iex',start,end)\n",
      "  File \"C:\\Users\\admin\\anaconda3\\lib\\site-packages\\pandas\\util\\_decorators.py\", line 207, in wrapper\n",
      "    return func(*args, **kwargs)\n",
      "  File \"C:\\Users\\admin\\anaconda3\\lib\\site-packages\\pandas_datareader\\data.py\", line 382, in DataReader\n",
      "    return IEXDailyReader(\n",
      "  File \"C:\\Users\\admin\\anaconda3\\lib\\site-packages\\pandas_datareader\\iex\\daily.py\", line 143, in read\n",
      "    return self._read_one_data(self.url, self._get_params(self.symbols))\n",
      "  File \"C:\\Users\\admin\\anaconda3\\lib\\site-packages\\pandas_datareader\\base.py\", line 108, in _read_one_data\n",
      "    out = self._read_url_as_StringIO(url, params=params)\n",
      "  File \"C:\\Users\\admin\\anaconda3\\lib\\site-packages\\pandas_datareader\\base.py\", line 119, in _read_url_as_StringIO\n",
      "    response = self._get_response(url, params=params)\n",
      "  File \"C:\\Users\\admin\\anaconda3\\lib\\site-packages\\pandas_datareader\\base.py\", line 181, in _get_response\n",
      "    raise RemoteDataError(msg)\n",
      "pandas_datareader._utils.RemoteDataError: Unable to read URL: https://cloud.iexapis.com/stable/stock/market/batch?symbols=&types=chart&range=max&token=pk_e124697d80704446893c52da182883c8\n",
      "Response Text:\n",
      "b'{\"error\":\"\\\\\"symbols\\\\\" is not allowed to be empty\"}'\n"
     ]
    },
    {
     "name": "stderr",
     "output_type": "stream",
     "text": [
      "127.0.0.1 - - [03/Jan/2023 02:04:03] \"POST /_dash-update-component HTTP/1.1\" 500 -\n"
     ]
    },
    {
     "name": "stdout",
     "output_type": "stream",
     "text": [
      "Exception on /_dash-update-component [POST]\n",
      "Traceback (most recent call last):\n",
      "  File \"C:\\Users\\admin\\anaconda3\\lib\\site-packages\\flask\\app.py\", line 2447, in wsgi_app\n",
      "    response = self.full_dispatch_request()\n",
      "  File \"C:\\Users\\admin\\anaconda3\\lib\\site-packages\\flask\\app.py\", line 1952, in full_dispatch_request\n",
      "    rv = self.handle_user_exception(e)\n",
      "  File \"C:\\Users\\admin\\anaconda3\\lib\\site-packages\\flask\\app.py\", line 1821, in handle_user_exception\n",
      "    reraise(exc_type, exc_value, tb)\n",
      "  File \"C:\\Users\\admin\\anaconda3\\lib\\site-packages\\flask\\_compat.py\", line 39, in reraise\n",
      "    raise value\n",
      "  File \"C:\\Users\\admin\\anaconda3\\lib\\site-packages\\flask\\app.py\", line 1950, in full_dispatch_request\n",
      "    rv = self.dispatch_request()\n",
      "  File \"C:\\Users\\admin\\anaconda3\\lib\\site-packages\\flask\\app.py\", line 1936, in dispatch_request\n",
      "    return self.view_functions[rule.endpoint](**req.view_args)\n",
      "  File \"C:\\Users\\admin\\anaconda3\\lib\\site-packages\\dash\\dash.py\", line 1274, in dispatch\n",
      "    ctx.run(\n",
      "  File \"C:\\Users\\admin\\anaconda3\\lib\\site-packages\\dash\\_callback.py\", line 440, in add_context\n",
      "    output_value = func(*func_args, **func_kwargs)  # %% callback invoked %%\n",
      "  File \"C:\\Users\\admin\\AppData\\Local\\Temp\\ipykernel_16924\\2990508254.py\", line 19, in stock_update\n",
      "    df=pdd.DataReader(stock_ticker,'iex',start,end)\n",
      "  File \"C:\\Users\\admin\\anaconda3\\lib\\site-packages\\pandas\\util\\_decorators.py\", line 207, in wrapper\n",
      "    return func(*args, **kwargs)\n",
      "  File \"C:\\Users\\admin\\anaconda3\\lib\\site-packages\\pandas_datareader\\data.py\", line 382, in DataReader\n",
      "    return IEXDailyReader(\n",
      "  File \"C:\\Users\\admin\\anaconda3\\lib\\site-packages\\pandas_datareader\\iex\\daily.py\", line 143, in read\n",
      "    return self._read_one_data(self.url, self._get_params(self.symbols))\n",
      "  File \"C:\\Users\\admin\\anaconda3\\lib\\site-packages\\pandas_datareader\\base.py\", line 113, in _read_one_data\n",
      "    return self._read_lines(out)\n",
      "  File \"C:\\Users\\admin\\anaconda3\\lib\\site-packages\\pandas_datareader\\iex\\daily.py\", line 156, in _read_lines\n",
      "    d = json_data.pop(symbol)[\"chart\"]\n",
      "KeyError: 'nfl'\n"
     ]
    },
    {
     "name": "stderr",
     "output_type": "stream",
     "text": [
      "127.0.0.1 - - [03/Jan/2023 02:04:04] \"POST /_dash-update-component HTTP/1.1\" 500 -\n",
      "127.0.0.1 - - [03/Jan/2023 02:04:05] \"POST /_dash-update-component HTTP/1.1\" 200 -\n"
     ]
    },
    {
     "name": "stdout",
     "output_type": "stream",
     "text": [
      "Exception on /_dash-update-component [POST]\n",
      "Traceback (most recent call last):\n",
      "  File \"C:\\Users\\admin\\anaconda3\\lib\\site-packages\\flask\\app.py\", line 2447, in wsgi_app\n",
      "    response = self.full_dispatch_request()\n",
      "  File \"C:\\Users\\admin\\anaconda3\\lib\\site-packages\\flask\\app.py\", line 1952, in full_dispatch_request\n",
      "    rv = self.handle_user_exception(e)\n",
      "  File \"C:\\Users\\admin\\anaconda3\\lib\\site-packages\\flask\\app.py\", line 1821, in handle_user_exception\n",
      "    reraise(exc_type, exc_value, tb)\n",
      "  File \"C:\\Users\\admin\\anaconda3\\lib\\site-packages\\flask\\_compat.py\", line 39, in reraise\n",
      "    raise value\n",
      "  File \"C:\\Users\\admin\\anaconda3\\lib\\site-packages\\flask\\app.py\", line 1950, in full_dispatch_request\n",
      "    rv = self.dispatch_request()\n",
      "  File \"C:\\Users\\admin\\anaconda3\\lib\\site-packages\\flask\\app.py\", line 1936, in dispatch_request\n",
      "    return self.view_functions[rule.endpoint](**req.view_args)\n",
      "  File \"C:\\Users\\admin\\anaconda3\\lib\\site-packages\\dash\\dash.py\", line 1274, in dispatch\n",
      "    ctx.run(\n",
      "  File \"C:\\Users\\admin\\anaconda3\\lib\\site-packages\\dash\\_callback.py\", line 440, in add_context\n",
      "    output_value = func(*func_args, **func_kwargs)  # %% callback invoked %%\n",
      "  File \"C:\\Users\\admin\\AppData\\Local\\Temp\\ipykernel_16924\\2990508254.py\", line 19, in stock_update\n",
      "    df=pdd.DataReader(stock_ticker,'iex',start,end)\n",
      "  File \"C:\\Users\\admin\\anaconda3\\lib\\site-packages\\pandas\\util\\_decorators.py\", line 207, in wrapper\n",
      "    return func(*args, **kwargs)\n",
      "  File \"C:\\Users\\admin\\anaconda3\\lib\\site-packages\\pandas_datareader\\data.py\", line 382, in DataReader\n",
      "    return IEXDailyReader(\n",
      "  File \"C:\\Users\\admin\\anaconda3\\lib\\site-packages\\pandas_datareader\\iex\\daily.py\", line 143, in read\n",
      "    return self._read_one_data(self.url, self._get_params(self.symbols))\n",
      "  File \"C:\\Users\\admin\\anaconda3\\lib\\site-packages\\pandas_datareader\\base.py\", line 108, in _read_one_data\n",
      "    out = self._read_url_as_StringIO(url, params=params)\n",
      "  File \"C:\\Users\\admin\\anaconda3\\lib\\site-packages\\pandas_datareader\\base.py\", line 119, in _read_url_as_StringIO\n",
      "    response = self._get_response(url, params=params)\n",
      "  File \"C:\\Users\\admin\\anaconda3\\lib\\site-packages\\pandas_datareader\\base.py\", line 181, in _get_response\n",
      "    raise RemoteDataError(msg)\n",
      "pandas_datareader._utils.RemoteDataError: Unable to read URL: https://cloud.iexapis.com/stable/stock/market/batch?symbols=nf&types=chart&range=max&token=pk_e124697d80704446893c52da182883c8\n"
     ]
    },
    {
     "name": "stderr",
     "output_type": "stream",
     "text": [
      "127.0.0.1 - - [03/Jan/2023 02:04:05] \"POST /_dash-update-component HTTP/1.1\" 500 -\n"
     ]
    },
    {
     "name": "stdout",
     "output_type": "stream",
     "text": [
      "Exception on /_dash-update-component [POST]\n",
      "Traceback (most recent call last):\n",
      "  File \"C:\\Users\\admin\\anaconda3\\lib\\site-packages\\flask\\app.py\", line 2447, in wsgi_app\n",
      "    response = self.full_dispatch_request()\n",
      "  File \"C:\\Users\\admin\\anaconda3\\lib\\site-packages\\flask\\app.py\", line 1952, in full_dispatch_request\n",
      "    rv = self.handle_user_exception(e)\n",
      "  File \"C:\\Users\\admin\\anaconda3\\lib\\site-packages\\flask\\app.py\", line 1821, in handle_user_exception\n",
      "    reraise(exc_type, exc_value, tb)\n",
      "  File \"C:\\Users\\admin\\anaconda3\\lib\\site-packages\\flask\\_compat.py\", line 39, in reraise\n",
      "    raise value\n",
      "  File \"C:\\Users\\admin\\anaconda3\\lib\\site-packages\\flask\\app.py\", line 1950, in full_dispatch_request\n",
      "    rv = self.dispatch_request()\n",
      "  File \"C:\\Users\\admin\\anaconda3\\lib\\site-packages\\flask\\app.py\", line 1936, in dispatch_request\n",
      "    return self.view_functions[rule.endpoint](**req.view_args)\n",
      "  File \"C:\\Users\\admin\\anaconda3\\lib\\site-packages\\dash\\dash.py\", line 1274, in dispatch\n",
      "    ctx.run(\n",
      "  File \"C:\\Users\\admin\\anaconda3\\lib\\site-packages\\dash\\_callback.py\", line 440, in add_context\n",
      "    output_value = func(*func_args, **func_kwargs)  # %% callback invoked %%\n",
      "  File \"C:\\Users\\admin\\AppData\\Local\\Temp\\ipykernel_16924\\2990508254.py\", line 19, in stock_update\n",
      "    df=pdd.DataReader(stock_ticker,'iex',start,end)\n",
      "  File \"C:\\Users\\admin\\anaconda3\\lib\\site-packages\\pandas\\util\\_decorators.py\", line 207, in wrapper\n",
      "    return func(*args, **kwargs)\n",
      "  File \"C:\\Users\\admin\\anaconda3\\lib\\site-packages\\pandas_datareader\\data.py\", line 382, in DataReader\n",
      "    return IEXDailyReader(\n",
      "  File \"C:\\Users\\admin\\anaconda3\\lib\\site-packages\\pandas_datareader\\iex\\daily.py\", line 143, in read\n",
      "    return self._read_one_data(self.url, self._get_params(self.symbols))\n",
      "  File \"C:\\Users\\admin\\anaconda3\\lib\\site-packages\\pandas_datareader\\base.py\", line 113, in _read_one_data\n",
      "    return self._read_lines(out)\n",
      "  File \"C:\\Users\\admin\\anaconda3\\lib\\site-packages\\pandas_datareader\\iex\\daily.py\", line 156, in _read_lines\n",
      "    d = json_data.pop(symbol)[\"chart\"]\n",
      "KeyError: 'n'\n"
     ]
    },
    {
     "name": "stderr",
     "output_type": "stream",
     "text": [
      "127.0.0.1 - - [03/Jan/2023 02:04:06] \"POST /_dash-update-component HTTP/1.1\" 500 -\n"
     ]
    },
    {
     "name": "stdout",
     "output_type": "stream",
     "text": [
      "Exception on /_dash-update-component [POST]\n",
      "Traceback (most recent call last):\n",
      "  File \"C:\\Users\\admin\\anaconda3\\lib\\site-packages\\flask\\app.py\", line 2447, in wsgi_app\n",
      "    response = self.full_dispatch_request()\n",
      "  File \"C:\\Users\\admin\\anaconda3\\lib\\site-packages\\flask\\app.py\", line 1952, in full_dispatch_request\n",
      "    rv = self.handle_user_exception(e)\n",
      "  File \"C:\\Users\\admin\\anaconda3\\lib\\site-packages\\flask\\app.py\", line 1821, in handle_user_exception\n",
      "    reraise(exc_type, exc_value, tb)\n",
      "  File \"C:\\Users\\admin\\anaconda3\\lib\\site-packages\\flask\\_compat.py\", line 39, in reraise\n",
      "    raise value\n",
      "  File \"C:\\Users\\admin\\anaconda3\\lib\\site-packages\\flask\\app.py\", line 1950, in full_dispatch_request\n",
      "    rv = self.dispatch_request()\n",
      "  File \"C:\\Users\\admin\\anaconda3\\lib\\site-packages\\flask\\app.py\", line 1936, in dispatch_request\n",
      "    return self.view_functions[rule.endpoint](**req.view_args)\n",
      "  File \"C:\\Users\\admin\\anaconda3\\lib\\site-packages\\dash\\dash.py\", line 1274, in dispatch\n",
      "    ctx.run(\n",
      "  File \"C:\\Users\\admin\\anaconda3\\lib\\site-packages\\dash\\_callback.py\", line 440, in add_context\n",
      "    output_value = func(*func_args, **func_kwargs)  # %% callback invoked %%\n",
      "  File \"C:\\Users\\admin\\AppData\\Local\\Temp\\ipykernel_16924\\2990508254.py\", line 19, in stock_update\n",
      "    df=pdd.DataReader(stock_ticker,'iex',start,end)\n",
      "  File \"C:\\Users\\admin\\anaconda3\\lib\\site-packages\\pandas\\util\\_decorators.py\", line 207, in wrapper\n",
      "    return func(*args, **kwargs)\n",
      "  File \"C:\\Users\\admin\\anaconda3\\lib\\site-packages\\pandas_datareader\\data.py\", line 382, in DataReader\n",
      "    return IEXDailyReader(\n",
      "  File \"C:\\Users\\admin\\anaconda3\\lib\\site-packages\\pandas_datareader\\iex\\daily.py\", line 143, in read\n",
      "    return self._read_one_data(self.url, self._get_params(self.symbols))\n",
      "  File \"C:\\Users\\admin\\anaconda3\\lib\\site-packages\\pandas_datareader\\base.py\", line 113, in _read_one_data\n",
      "    return self._read_lines(out)\n",
      "  File \"C:\\Users\\admin\\anaconda3\\lib\\site-packages\\pandas_datareader\\iex\\daily.py\", line 156, in _read_lines\n",
      "    d = json_data.pop(symbol)[\"chart\"]\n",
      "KeyError: 'nflx'\n"
     ]
    },
    {
     "name": "stderr",
     "output_type": "stream",
     "text": [
      "127.0.0.1 - - [03/Jan/2023 02:04:06] \"POST /_dash-update-component HTTP/1.1\" 500 -\n"
     ]
    },
    {
     "name": "stdout",
     "output_type": "stream",
     "text": [
      "Exception on /_dash-update-component [POST]\n",
      "Traceback (most recent call last):\n",
      "  File \"C:\\Users\\admin\\anaconda3\\lib\\site-packages\\flask\\app.py\", line 2447, in wsgi_app\n",
      "    response = self.full_dispatch_request()\n",
      "  File \"C:\\Users\\admin\\anaconda3\\lib\\site-packages\\flask\\app.py\", line 1952, in full_dispatch_request\n",
      "    rv = self.handle_user_exception(e)\n",
      "  File \"C:\\Users\\admin\\anaconda3\\lib\\site-packages\\flask\\app.py\", line 1821, in handle_user_exception\n",
      "    reraise(exc_type, exc_value, tb)\n",
      "  File \"C:\\Users\\admin\\anaconda3\\lib\\site-packages\\flask\\_compat.py\", line 39, in reraise\n",
      "    raise value\n",
      "  File \"C:\\Users\\admin\\anaconda3\\lib\\site-packages\\flask\\app.py\", line 1950, in full_dispatch_request\n",
      "    rv = self.dispatch_request()\n",
      "  File \"C:\\Users\\admin\\anaconda3\\lib\\site-packages\\flask\\app.py\", line 1936, in dispatch_request\n",
      "    return self.view_functions[rule.endpoint](**req.view_args)\n",
      "  File \"C:\\Users\\admin\\anaconda3\\lib\\site-packages\\dash\\dash.py\", line 1274, in dispatch\n",
      "    ctx.run(\n",
      "  File \"C:\\Users\\admin\\anaconda3\\lib\\site-packages\\dash\\_callback.py\", line 440, in add_context\n",
      "    output_value = func(*func_args, **func_kwargs)  # %% callback invoked %%\n",
      "  File \"C:\\Users\\admin\\AppData\\Local\\Temp\\ipykernel_16924\\2990508254.py\", line 19, in stock_update\n",
      "    df=pdd.DataReader(stock_ticker,'iex',start,end)\n",
      "  File \"C:\\Users\\admin\\anaconda3\\lib\\site-packages\\pandas\\util\\_decorators.py\", line 207, in wrapper\n",
      "    return func(*args, **kwargs)\n",
      "  File \"C:\\Users\\admin\\anaconda3\\lib\\site-packages\\pandas_datareader\\data.py\", line 382, in DataReader\n",
      "    return IEXDailyReader(\n",
      "  File \"C:\\Users\\admin\\anaconda3\\lib\\site-packages\\pandas_datareader\\iex\\daily.py\", line 143, in read\n",
      "    return self._read_one_data(self.url, self._get_params(self.symbols))\n",
      "  File \"C:\\Users\\admin\\anaconda3\\lib\\site-packages\\pandas_datareader\\base.py\", line 113, in _read_one_data\n",
      "    return self._read_lines(out)\n",
      "  File \"C:\\Users\\admin\\anaconda3\\lib\\site-packages\\pandas_datareader\\iex\\daily.py\", line 156, in _read_lines\n",
      "    d = json_data.pop(symbol)[\"chart\"]\n",
      "KeyError: 'nfl'\n"
     ]
    },
    {
     "name": "stderr",
     "output_type": "stream",
     "text": [
      "127.0.0.1 - - [03/Jan/2023 02:04:06] \"POST /_dash-update-component HTTP/1.1\" 500 -\n"
     ]
    },
    {
     "name": "stdout",
     "output_type": "stream",
     "text": [
      "Exception on /_dash-update-component [POST]\n",
      "Traceback (most recent call last):\n",
      "  File \"C:\\Users\\admin\\anaconda3\\lib\\site-packages\\flask\\app.py\", line 2447, in wsgi_app\n",
      "    response = self.full_dispatch_request()\n",
      "  File \"C:\\Users\\admin\\anaconda3\\lib\\site-packages\\flask\\app.py\", line 1952, in full_dispatch_request\n",
      "    rv = self.handle_user_exception(e)\n",
      "  File \"C:\\Users\\admin\\anaconda3\\lib\\site-packages\\flask\\app.py\", line 1821, in handle_user_exception\n",
      "    reraise(exc_type, exc_value, tb)\n",
      "  File \"C:\\Users\\admin\\anaconda3\\lib\\site-packages\\flask\\_compat.py\", line 39, in reraise\n",
      "    raise value\n",
      "  File \"C:\\Users\\admin\\anaconda3\\lib\\site-packages\\flask\\app.py\", line 1950, in full_dispatch_request\n",
      "    rv = self.dispatch_request()\n",
      "  File \"C:\\Users\\admin\\anaconda3\\lib\\site-packages\\flask\\app.py\", line 1936, in dispatch_request\n",
      "    return self.view_functions[rule.endpoint](**req.view_args)\n",
      "  File \"C:\\Users\\admin\\anaconda3\\lib\\site-packages\\dash\\dash.py\", line 1274, in dispatch\n",
      "    ctx.run(\n",
      "  File \"C:\\Users\\admin\\anaconda3\\lib\\site-packages\\dash\\_callback.py\", line 440, in add_context\n",
      "    output_value = func(*func_args, **func_kwargs)  # %% callback invoked %%\n",
      "  File \"C:\\Users\\admin\\AppData\\Local\\Temp\\ipykernel_16924\\2990508254.py\", line 19, in stock_update\n",
      "    df=pdd.DataReader(stock_ticker,'iex',start,end)\n",
      "  File \"C:\\Users\\admin\\anaconda3\\lib\\site-packages\\pandas\\util\\_decorators.py\", line 207, in wrapper\n",
      "    return func(*args, **kwargs)\n",
      "  File \"C:\\Users\\admin\\anaconda3\\lib\\site-packages\\pandas_datareader\\data.py\", line 382, in DataReader\n",
      "    return IEXDailyReader(\n",
      "  File \"C:\\Users\\admin\\anaconda3\\lib\\site-packages\\pandas_datareader\\iex\\daily.py\", line 143, in read\n",
      "    return self._read_one_data(self.url, self._get_params(self.symbols))\n",
      "  File \"C:\\Users\\admin\\anaconda3\\lib\\site-packages\\pandas_datareader\\base.py\", line 108, in _read_one_data\n",
      "    out = self._read_url_as_StringIO(url, params=params)\n",
      "  File \"C:\\Users\\admin\\anaconda3\\lib\\site-packages\\pandas_datareader\\base.py\", line 119, in _read_url_as_StringIO\n",
      "    response = self._get_response(url, params=params)\n",
      "  File \"C:\\Users\\admin\\anaconda3\\lib\\site-packages\\pandas_datareader\\base.py\", line 181, in _get_response\n",
      "    raise RemoteDataError(msg)\n",
      "pandas_datareader._utils.RemoteDataError: Unable to read URL: https://cloud.iexapis.com/stable/stock/market/batch?symbols=nf&types=chart&range=max&token=pk_e124697d80704446893c52da182883c8\n"
     ]
    },
    {
     "name": "stderr",
     "output_type": "stream",
     "text": [
      "127.0.0.1 - - [03/Jan/2023 02:04:07] \"POST /_dash-update-component HTTP/1.1\" 500 -\n"
     ]
    },
    {
     "name": "stdout",
     "output_type": "stream",
     "text": [
      "Exception on /_dash-update-component [POST]\n",
      "Traceback (most recent call last):\n",
      "  File \"C:\\Users\\admin\\anaconda3\\lib\\site-packages\\flask\\app.py\", line 2447, in wsgi_app\n",
      "    response = self.full_dispatch_request()\n",
      "  File \"C:\\Users\\admin\\anaconda3\\lib\\site-packages\\flask\\app.py\", line 1952, in full_dispatch_request\n",
      "    rv = self.handle_user_exception(e)\n",
      "  File \"C:\\Users\\admin\\anaconda3\\lib\\site-packages\\flask\\app.py\", line 1821, in handle_user_exception\n",
      "    reraise(exc_type, exc_value, tb)\n",
      "  File \"C:\\Users\\admin\\anaconda3\\lib\\site-packages\\flask\\_compat.py\", line 39, in reraise\n",
      "    raise value\n",
      "  File \"C:\\Users\\admin\\anaconda3\\lib\\site-packages\\flask\\app.py\", line 1950, in full_dispatch_request\n",
      "    rv = self.dispatch_request()\n",
      "  File \"C:\\Users\\admin\\anaconda3\\lib\\site-packages\\flask\\app.py\", line 1936, in dispatch_request\n",
      "    return self.view_functions[rule.endpoint](**req.view_args)\n",
      "  File \"C:\\Users\\admin\\anaconda3\\lib\\site-packages\\dash\\dash.py\", line 1274, in dispatch\n",
      "    ctx.run(\n",
      "  File \"C:\\Users\\admin\\anaconda3\\lib\\site-packages\\dash\\_callback.py\", line 440, in add_context\n",
      "    output_value = func(*func_args, **func_kwargs)  # %% callback invoked %%\n",
      "  File \"C:\\Users\\admin\\AppData\\Local\\Temp\\ipykernel_16924\\2990508254.py\", line 19, in stock_update\n",
      "    df=pdd.DataReader(stock_ticker,'iex',start,end)\n",
      "  File \"C:\\Users\\admin\\anaconda3\\lib\\site-packages\\pandas\\util\\_decorators.py\", line 207, in wrapper\n",
      "    return func(*args, **kwargs)\n",
      "  File \"C:\\Users\\admin\\anaconda3\\lib\\site-packages\\pandas_datareader\\data.py\", line 382, in DataReader\n",
      "    return IEXDailyReader(\n",
      "  File \"C:\\Users\\admin\\anaconda3\\lib\\site-packages\\pandas_datareader\\iex\\daily.py\", line 143, in read\n",
      "    return self._read_one_data(self.url, self._get_params(self.symbols))\n",
      "  File \"C:\\Users\\admin\\anaconda3\\lib\\site-packages\\pandas_datareader\\base.py\", line 108, in _read_one_data\n",
      "    out = self._read_url_as_StringIO(url, params=params)\n",
      "  File \"C:\\Users\\admin\\anaconda3\\lib\\site-packages\\pandas_datareader\\base.py\", line 119, in _read_url_as_StringIO\n",
      "    response = self._get_response(url, params=params)\n",
      "  File \"C:\\Users\\admin\\anaconda3\\lib\\site-packages\\pandas_datareader\\base.py\", line 181, in _get_response\n",
      "    raise RemoteDataError(msg)\n",
      "pandas_datareader._utils.RemoteDataError: Unable to read URL: https://cloud.iexapis.com/stable/stock/market/batch?symbols=&types=chart&range=max&token=pk_e124697d80704446893c52da182883c8\n",
      "Response Text:\n",
      "b'{\"error\":\"\\\\\"symbols\\\\\" is not allowed to be empty\"}'\n"
     ]
    },
    {
     "name": "stderr",
     "output_type": "stream",
     "text": [
      "127.0.0.1 - - [03/Jan/2023 02:04:07] \"POST /_dash-update-component HTTP/1.1\" 500 -\n"
     ]
    },
    {
     "name": "stdout",
     "output_type": "stream",
     "text": [
      "Exception on /_dash-update-component [POST]\n",
      "Traceback (most recent call last):\n",
      "  File \"C:\\Users\\admin\\anaconda3\\lib\\site-packages\\flask\\app.py\", line 2447, in wsgi_app\n",
      "    response = self.full_dispatch_request()\n",
      "  File \"C:\\Users\\admin\\anaconda3\\lib\\site-packages\\flask\\app.py\", line 1952, in full_dispatch_request\n",
      "    rv = self.handle_user_exception(e)\n",
      "  File \"C:\\Users\\admin\\anaconda3\\lib\\site-packages\\flask\\app.py\", line 1821, in handle_user_exception\n",
      "    reraise(exc_type, exc_value, tb)\n",
      "  File \"C:\\Users\\admin\\anaconda3\\lib\\site-packages\\flask\\_compat.py\", line 39, in reraise\n",
      "    raise value\n",
      "  File \"C:\\Users\\admin\\anaconda3\\lib\\site-packages\\flask\\app.py\", line 1950, in full_dispatch_request\n",
      "    rv = self.dispatch_request()\n",
      "  File \"C:\\Users\\admin\\anaconda3\\lib\\site-packages\\flask\\app.py\", line 1936, in dispatch_request\n",
      "    return self.view_functions[rule.endpoint](**req.view_args)\n",
      "  File \"C:\\Users\\admin\\anaconda3\\lib\\site-packages\\dash\\dash.py\", line 1274, in dispatch\n",
      "    ctx.run(\n",
      "  File \"C:\\Users\\admin\\anaconda3\\lib\\site-packages\\dash\\_callback.py\", line 440, in add_context\n",
      "    output_value = func(*func_args, **func_kwargs)  # %% callback invoked %%\n",
      "  File \"C:\\Users\\admin\\AppData\\Local\\Temp\\ipykernel_16924\\2990508254.py\", line 19, in stock_update\n",
      "    df=pdd.DataReader(stock_ticker,'iex',start,end)\n",
      "  File \"C:\\Users\\admin\\anaconda3\\lib\\site-packages\\pandas\\util\\_decorators.py\", line 207, in wrapper\n",
      "    return func(*args, **kwargs)\n",
      "  File \"C:\\Users\\admin\\anaconda3\\lib\\site-packages\\pandas_datareader\\data.py\", line 382, in DataReader\n",
      "    return IEXDailyReader(\n",
      "  File \"C:\\Users\\admin\\anaconda3\\lib\\site-packages\\pandas_datareader\\iex\\daily.py\", line 143, in read\n",
      "    return self._read_one_data(self.url, self._get_params(self.symbols))\n",
      "  File \"C:\\Users\\admin\\anaconda3\\lib\\site-packages\\pandas_datareader\\base.py\", line 113, in _read_one_data\n",
      "    return self._read_lines(out)\n",
      "  File \"C:\\Users\\admin\\anaconda3\\lib\\site-packages\\pandas_datareader\\iex\\daily.py\", line 158, in _read_lines\n",
      "    df.set_index(\"date\", inplace=True)\n",
      "  File \"C:\\Users\\admin\\anaconda3\\lib\\site-packages\\pandas\\util\\_decorators.py\", line 311, in wrapper\n",
      "    return func(*args, **kwargs)\n",
      "  File \"C:\\Users\\admin\\anaconda3\\lib\\site-packages\\pandas\\core\\frame.py\", line 5494, in set_index\n",
      "    raise KeyError(f\"None of {missing} are in the columns\")\n",
      "KeyError: \"None of ['date'] are in the columns\"\n"
     ]
    },
    {
     "name": "stderr",
     "output_type": "stream",
     "text": [
      "127.0.0.1 - - [03/Jan/2023 02:04:17] \"POST /_dash-update-component HTTP/1.1\" 500 -\n"
     ]
    },
    {
     "name": "stdout",
     "output_type": "stream",
     "text": [
      "Exception on /_dash-update-component [POST]\n",
      "Traceback (most recent call last):\n",
      "  File \"C:\\Users\\admin\\anaconda3\\lib\\site-packages\\flask\\app.py\", line 2447, in wsgi_app\n",
      "    response = self.full_dispatch_request()\n",
      "  File \"C:\\Users\\admin\\anaconda3\\lib\\site-packages\\flask\\app.py\", line 1952, in full_dispatch_request\n",
      "    rv = self.handle_user_exception(e)\n",
      "  File \"C:\\Users\\admin\\anaconda3\\lib\\site-packages\\flask\\app.py\", line 1821, in handle_user_exception\n",
      "    reraise(exc_type, exc_value, tb)\n",
      "  File \"C:\\Users\\admin\\anaconda3\\lib\\site-packages\\flask\\_compat.py\", line 39, in reraise\n",
      "    raise value\n",
      "  File \"C:\\Users\\admin\\anaconda3\\lib\\site-packages\\flask\\app.py\", line 1950, in full_dispatch_request\n",
      "    rv = self.dispatch_request()\n",
      "  File \"C:\\Users\\admin\\anaconda3\\lib\\site-packages\\flask\\app.py\", line 1936, in dispatch_request\n",
      "    return self.view_functions[rule.endpoint](**req.view_args)\n",
      "  File \"C:\\Users\\admin\\anaconda3\\lib\\site-packages\\dash\\dash.py\", line 1274, in dispatch\n",
      "    ctx.run(\n",
      "  File \"C:\\Users\\admin\\anaconda3\\lib\\site-packages\\dash\\_callback.py\", line 440, in add_context\n",
      "    output_value = func(*func_args, **func_kwargs)  # %% callback invoked %%\n",
      "  File \"C:\\Users\\admin\\AppData\\Local\\Temp\\ipykernel_16924\\2990508254.py\", line 19, in stock_update\n",
      "    df=pdd.DataReader(stock_ticker,'iex',start,end)\n",
      "  File \"C:\\Users\\admin\\anaconda3\\lib\\site-packages\\pandas\\util\\_decorators.py\", line 207, in wrapper\n",
      "    return func(*args, **kwargs)\n",
      "  File \"C:\\Users\\admin\\anaconda3\\lib\\site-packages\\pandas_datareader\\data.py\", line 382, in DataReader\n",
      "    return IEXDailyReader(\n",
      "  File \"C:\\Users\\admin\\anaconda3\\lib\\site-packages\\pandas_datareader\\iex\\daily.py\", line 143, in read\n",
      "    return self._read_one_data(self.url, self._get_params(self.symbols))\n",
      "  File \"C:\\Users\\admin\\anaconda3\\lib\\site-packages\\pandas_datareader\\base.py\", line 113, in _read_one_data\n",
      "    return self._read_lines(out)\n",
      "  File \"C:\\Users\\admin\\anaconda3\\lib\\site-packages\\pandas_datareader\\iex\\daily.py\", line 158, in _read_lines\n",
      "    df.set_index(\"date\", inplace=True)\n",
      "  File \"C:\\Users\\admin\\anaconda3\\lib\\site-packages\\pandas\\util\\_decorators.py\", line 311, in wrapper\n",
      "    return func(*args, **kwargs)\n",
      "  File \"C:\\Users\\admin\\anaconda3\\lib\\site-packages\\pandas\\core\\frame.py\", line 5494, in set_index\n",
      "    raise KeyError(f\"None of {missing} are in the columns\")\n",
      "KeyError: \"None of ['date'] are in the columns\"\n"
     ]
    },
    {
     "name": "stderr",
     "output_type": "stream",
     "text": [
      "127.0.0.1 - - [03/Jan/2023 02:04:19] \"POST /_dash-update-component HTTP/1.1\" 500 -\n"
     ]
    },
    {
     "name": "stdout",
     "output_type": "stream",
     "text": [
      "Exception on /_dash-update-component [POST]\n",
      "Traceback (most recent call last):\n",
      "  File \"C:\\Users\\admin\\anaconda3\\lib\\site-packages\\flask\\app.py\", line 2447, in wsgi_app\n",
      "    response = self.full_dispatch_request()\n",
      "  File \"C:\\Users\\admin\\anaconda3\\lib\\site-packages\\flask\\app.py\", line 1952, in full_dispatch_request\n",
      "    rv = self.handle_user_exception(e)\n",
      "  File \"C:\\Users\\admin\\anaconda3\\lib\\site-packages\\flask\\app.py\", line 1821, in handle_user_exception\n",
      "    reraise(exc_type, exc_value, tb)\n",
      "  File \"C:\\Users\\admin\\anaconda3\\lib\\site-packages\\flask\\_compat.py\", line 39, in reraise\n",
      "    raise value\n",
      "  File \"C:\\Users\\admin\\anaconda3\\lib\\site-packages\\flask\\app.py\", line 1950, in full_dispatch_request\n",
      "    rv = self.dispatch_request()\n",
      "  File \"C:\\Users\\admin\\anaconda3\\lib\\site-packages\\flask\\app.py\", line 1936, in dispatch_request\n",
      "    return self.view_functions[rule.endpoint](**req.view_args)\n",
      "  File \"C:\\Users\\admin\\anaconda3\\lib\\site-packages\\dash\\dash.py\", line 1274, in dispatch\n",
      "    ctx.run(\n",
      "  File \"C:\\Users\\admin\\anaconda3\\lib\\site-packages\\dash\\_callback.py\", line 440, in add_context\n",
      "    output_value = func(*func_args, **func_kwargs)  # %% callback invoked %%\n",
      "  File \"C:\\Users\\admin\\AppData\\Local\\Temp\\ipykernel_16924\\2990508254.py\", line 19, in stock_update\n",
      "    df=pdd.DataReader(stock_ticker,'iex',start,end)\n",
      "  File \"C:\\Users\\admin\\anaconda3\\lib\\site-packages\\pandas\\util\\_decorators.py\", line 207, in wrapper\n",
      "    return func(*args, **kwargs)\n",
      "  File \"C:\\Users\\admin\\anaconda3\\lib\\site-packages\\pandas_datareader\\data.py\", line 382, in DataReader\n",
      "    return IEXDailyReader(\n",
      "  File \"C:\\Users\\admin\\anaconda3\\lib\\site-packages\\pandas_datareader\\iex\\daily.py\", line 143, in read\n",
      "    return self._read_one_data(self.url, self._get_params(self.symbols))\n",
      "  File \"C:\\Users\\admin\\anaconda3\\lib\\site-packages\\pandas_datareader\\base.py\", line 108, in _read_one_data\n",
      "    out = self._read_url_as_StringIO(url, params=params)\n",
      "  File \"C:\\Users\\admin\\anaconda3\\lib\\site-packages\\pandas_datareader\\base.py\", line 119, in _read_url_as_StringIO\n",
      "    response = self._get_response(url, params=params)\n",
      "  File \"C:\\Users\\admin\\anaconda3\\lib\\site-packages\\pandas_datareader\\base.py\", line 181, in _get_response\n",
      "    raise RemoteDataError(msg)\n",
      "pandas_datareader._utils.RemoteDataError: Unable to read URL: https://cloud.iexapis.com/stable/stock/market/batch?symbols=NF&types=chart&range=max&token=pk_e124697d80704446893c52da182883c8\n"
     ]
    },
    {
     "name": "stderr",
     "output_type": "stream",
     "text": [
      "127.0.0.1 - - [03/Jan/2023 02:04:19] \"POST /_dash-update-component HTTP/1.1\" 500 -\n",
      "127.0.0.1 - - [03/Jan/2023 02:04:22] \"POST /_dash-update-component HTTP/1.1\" 200 -\n"
     ]
    },
    {
     "name": "stdout",
     "output_type": "stream",
     "text": [
      "Exception on /_dash-update-component [POST]\n",
      "Traceback (most recent call last):\n",
      "  File \"C:\\Users\\admin\\anaconda3\\lib\\site-packages\\flask\\app.py\", line 2447, in wsgi_app\n",
      "    response = self.full_dispatch_request()\n",
      "  File \"C:\\Users\\admin\\anaconda3\\lib\\site-packages\\flask\\app.py\", line 1952, in full_dispatch_request\n",
      "    rv = self.handle_user_exception(e)\n",
      "  File \"C:\\Users\\admin\\anaconda3\\lib\\site-packages\\flask\\app.py\", line 1821, in handle_user_exception\n",
      "    reraise(exc_type, exc_value, tb)\n",
      "  File \"C:\\Users\\admin\\anaconda3\\lib\\site-packages\\flask\\_compat.py\", line 39, in reraise\n",
      "    raise value\n",
      "  File \"C:\\Users\\admin\\anaconda3\\lib\\site-packages\\flask\\app.py\", line 1950, in full_dispatch_request\n",
      "    rv = self.dispatch_request()\n",
      "  File \"C:\\Users\\admin\\anaconda3\\lib\\site-packages\\flask\\app.py\", line 1936, in dispatch_request\n",
      "    return self.view_functions[rule.endpoint](**req.view_args)\n",
      "  File \"C:\\Users\\admin\\anaconda3\\lib\\site-packages\\dash\\dash.py\", line 1274, in dispatch\n",
      "    ctx.run(\n",
      "  File \"C:\\Users\\admin\\anaconda3\\lib\\site-packages\\dash\\_callback.py\", line 440, in add_context\n",
      "    output_value = func(*func_args, **func_kwargs)  # %% callback invoked %%\n",
      "  File \"C:\\Users\\admin\\AppData\\Local\\Temp\\ipykernel_16924\\2990508254.py\", line 19, in stock_update\n",
      "    df=pdd.DataReader(stock_ticker,'iex',start,end)\n",
      "  File \"C:\\Users\\admin\\anaconda3\\lib\\site-packages\\pandas\\util\\_decorators.py\", line 207, in wrapper\n",
      "    return func(*args, **kwargs)\n",
      "  File \"C:\\Users\\admin\\anaconda3\\lib\\site-packages\\pandas_datareader\\data.py\", line 382, in DataReader\n",
      "    return IEXDailyReader(\n",
      "  File \"C:\\Users\\admin\\anaconda3\\lib\\site-packages\\pandas_datareader\\iex\\daily.py\", line 143, in read\n",
      "    return self._read_one_data(self.url, self._get_params(self.symbols))\n",
      "  File \"C:\\Users\\admin\\anaconda3\\lib\\site-packages\\pandas_datareader\\base.py\", line 113, in _read_one_data\n",
      "    return self._read_lines(out)\n",
      "  File \"C:\\Users\\admin\\anaconda3\\lib\\site-packages\\pandas_datareader\\iex\\daily.py\", line 158, in _read_lines\n",
      "    df.set_index(\"date\", inplace=True)\n",
      "  File \"C:\\Users\\admin\\anaconda3\\lib\\site-packages\\pandas\\util\\_decorators.py\", line 311, in wrapper\n",
      "    return func(*args, **kwargs)\n",
      "  File \"C:\\Users\\admin\\anaconda3\\lib\\site-packages\\pandas\\core\\frame.py\", line 5494, in set_index\n",
      "    raise KeyError(f\"None of {missing} are in the columns\")\n",
      "KeyError: \"None of ['date'] are in the columns\"\n"
     ]
    },
    {
     "name": "stderr",
     "output_type": "stream",
     "text": [
      "127.0.0.1 - - [03/Jan/2023 02:05:12] \"POST /_dash-update-component HTTP/1.1\" 500 -\n"
     ]
    },
    {
     "name": "stdout",
     "output_type": "stream",
     "text": [
      "Exception on /_dash-update-component [POST]\n",
      "Traceback (most recent call last):\n",
      "  File \"C:\\Users\\admin\\anaconda3\\lib\\site-packages\\flask\\app.py\", line 2447, in wsgi_app\n",
      "    response = self.full_dispatch_request()\n",
      "  File \"C:\\Users\\admin\\anaconda3\\lib\\site-packages\\flask\\app.py\", line 1952, in full_dispatch_request\n",
      "    rv = self.handle_user_exception(e)\n",
      "  File \"C:\\Users\\admin\\anaconda3\\lib\\site-packages\\flask\\app.py\", line 1821, in handle_user_exception\n",
      "    reraise(exc_type, exc_value, tb)\n",
      "  File \"C:\\Users\\admin\\anaconda3\\lib\\site-packages\\flask\\_compat.py\", line 39, in reraise\n",
      "    raise value\n",
      "  File \"C:\\Users\\admin\\anaconda3\\lib\\site-packages\\flask\\app.py\", line 1950, in full_dispatch_request\n",
      "    rv = self.dispatch_request()\n",
      "  File \"C:\\Users\\admin\\anaconda3\\lib\\site-packages\\flask\\app.py\", line 1936, in dispatch_request\n",
      "    return self.view_functions[rule.endpoint](**req.view_args)\n",
      "  File \"C:\\Users\\admin\\anaconda3\\lib\\site-packages\\dash\\dash.py\", line 1274, in dispatch\n",
      "    ctx.run(\n",
      "  File \"C:\\Users\\admin\\anaconda3\\lib\\site-packages\\dash\\_callback.py\", line 440, in add_context\n",
      "    output_value = func(*func_args, **func_kwargs)  # %% callback invoked %%\n",
      "  File \"C:\\Users\\admin\\AppData\\Local\\Temp\\ipykernel_16924\\2990508254.py\", line 19, in stock_update\n",
      "    df=pdd.DataReader(stock_ticker,'iex',start,end)\n",
      "  File \"C:\\Users\\admin\\anaconda3\\lib\\site-packages\\pandas\\util\\_decorators.py\", line 207, in wrapper\n",
      "    return func(*args, **kwargs)\n",
      "  File \"C:\\Users\\admin\\anaconda3\\lib\\site-packages\\pandas_datareader\\data.py\", line 382, in DataReader\n",
      "    return IEXDailyReader(\n",
      "  File \"C:\\Users\\admin\\anaconda3\\lib\\site-packages\\pandas_datareader\\iex\\daily.py\", line 143, in read\n",
      "    return self._read_one_data(self.url, self._get_params(self.symbols))\n",
      "  File \"C:\\Users\\admin\\anaconda3\\lib\\site-packages\\pandas_datareader\\base.py\", line 113, in _read_one_data\n",
      "    return self._read_lines(out)\n",
      "  File \"C:\\Users\\admin\\anaconda3\\lib\\site-packages\\pandas_datareader\\iex\\daily.py\", line 158, in _read_lines\n",
      "    df.set_index(\"date\", inplace=True)\n",
      "  File \"C:\\Users\\admin\\anaconda3\\lib\\site-packages\\pandas\\util\\_decorators.py\", line 311, in wrapper\n",
      "    return func(*args, **kwargs)\n",
      "  File \"C:\\Users\\admin\\anaconda3\\lib\\site-packages\\pandas\\core\\frame.py\", line 5494, in set_index\n",
      "    raise KeyError(f\"None of {missing} are in the columns\")\n",
      "KeyError: \"None of ['date'] are in the columns\"\n"
     ]
    },
    {
     "name": "stderr",
     "output_type": "stream",
     "text": [
      "127.0.0.1 - - [03/Jan/2023 02:05:13] \"POST /_dash-update-component HTTP/1.1\" 500 -\n"
     ]
    },
    {
     "name": "stdout",
     "output_type": "stream",
     "text": [
      "Exception on /_dash-update-component [POST]\n",
      "Traceback (most recent call last):\n",
      "  File \"C:\\Users\\admin\\anaconda3\\lib\\site-packages\\flask\\app.py\", line 2447, in wsgi_app\n",
      "    response = self.full_dispatch_request()\n",
      "  File \"C:\\Users\\admin\\anaconda3\\lib\\site-packages\\flask\\app.py\", line 1952, in full_dispatch_request\n",
      "    rv = self.handle_user_exception(e)\n",
      "  File \"C:\\Users\\admin\\anaconda3\\lib\\site-packages\\flask\\app.py\", line 1821, in handle_user_exception\n",
      "    reraise(exc_type, exc_value, tb)\n",
      "  File \"C:\\Users\\admin\\anaconda3\\lib\\site-packages\\flask\\_compat.py\", line 39, in reraise\n",
      "    raise value\n",
      "  File \"C:\\Users\\admin\\anaconda3\\lib\\site-packages\\flask\\app.py\", line 1950, in full_dispatch_request\n",
      "    rv = self.dispatch_request()\n",
      "  File \"C:\\Users\\admin\\anaconda3\\lib\\site-packages\\flask\\app.py\", line 1936, in dispatch_request\n",
      "    return self.view_functions[rule.endpoint](**req.view_args)\n",
      "  File \"C:\\Users\\admin\\anaconda3\\lib\\site-packages\\dash\\dash.py\", line 1274, in dispatch\n",
      "    ctx.run(\n",
      "  File \"C:\\Users\\admin\\anaconda3\\lib\\site-packages\\dash\\_callback.py\", line 440, in add_context\n",
      "    output_value = func(*func_args, **func_kwargs)  # %% callback invoked %%\n",
      "  File \"C:\\Users\\admin\\AppData\\Local\\Temp\\ipykernel_16924\\2990508254.py\", line 19, in stock_update\n",
      "    df=pdd.DataReader(stock_ticker,'iex',start,end)\n",
      "  File \"C:\\Users\\admin\\anaconda3\\lib\\site-packages\\pandas\\util\\_decorators.py\", line 207, in wrapper\n",
      "    return func(*args, **kwargs)\n",
      "  File \"C:\\Users\\admin\\anaconda3\\lib\\site-packages\\pandas_datareader\\data.py\", line 382, in DataReader\n",
      "    return IEXDailyReader(\n",
      "  File \"C:\\Users\\admin\\anaconda3\\lib\\site-packages\\pandas_datareader\\iex\\daily.py\", line 143, in read\n",
      "    return self._read_one_data(self.url, self._get_params(self.symbols))\n",
      "  File \"C:\\Users\\admin\\anaconda3\\lib\\site-packages\\pandas_datareader\\base.py\", line 108, in _read_one_data\n",
      "    out = self._read_url_as_StringIO(url, params=params)\n",
      "  File \"C:\\Users\\admin\\anaconda3\\lib\\site-packages\\pandas_datareader\\base.py\", line 119, in _read_url_as_StringIO\n",
      "    response = self._get_response(url, params=params)\n",
      "  File \"C:\\Users\\admin\\anaconda3\\lib\\site-packages\\pandas_datareader\\base.py\", line 181, in _get_response\n",
      "    raise RemoteDataError(msg)\n",
      "pandas_datareader._utils.RemoteDataError: Unable to read URL: https://cloud.iexapis.com/stable/stock/market/batch?symbols=&types=chart&range=max&token=pk_e124697d80704446893c52da182883c8\n",
      "Response Text:\n",
      "b'{\"error\":\"\\\\\"symbols\\\\\" is not allowed to be empty\"}'\n"
     ]
    },
    {
     "name": "stderr",
     "output_type": "stream",
     "text": [
      "127.0.0.1 - - [03/Jan/2023 02:05:15] \"POST /_dash-update-component HTTP/1.1\" 500 -\n"
     ]
    },
    {
     "name": "stdout",
     "output_type": "stream",
     "text": [
      "Exception on /_dash-update-component [POST]\n",
      "Traceback (most recent call last):\n",
      "  File \"C:\\Users\\admin\\anaconda3\\lib\\site-packages\\flask\\app.py\", line 2447, in wsgi_app\n",
      "    response = self.full_dispatch_request()\n",
      "  File \"C:\\Users\\admin\\anaconda3\\lib\\site-packages\\flask\\app.py\", line 1952, in full_dispatch_request\n",
      "    rv = self.handle_user_exception(e)\n",
      "  File \"C:\\Users\\admin\\anaconda3\\lib\\site-packages\\flask\\app.py\", line 1821, in handle_user_exception\n",
      "    reraise(exc_type, exc_value, tb)\n",
      "  File \"C:\\Users\\admin\\anaconda3\\lib\\site-packages\\flask\\_compat.py\", line 39, in reraise\n",
      "    raise value\n",
      "  File \"C:\\Users\\admin\\anaconda3\\lib\\site-packages\\flask\\app.py\", line 1950, in full_dispatch_request\n",
      "    rv = self.dispatch_request()\n",
      "  File \"C:\\Users\\admin\\anaconda3\\lib\\site-packages\\flask\\app.py\", line 1936, in dispatch_request\n",
      "    return self.view_functions[rule.endpoint](**req.view_args)\n",
      "  File \"C:\\Users\\admin\\anaconda3\\lib\\site-packages\\dash\\dash.py\", line 1274, in dispatch\n",
      "    ctx.run(\n",
      "  File \"C:\\Users\\admin\\anaconda3\\lib\\site-packages\\dash\\_callback.py\", line 440, in add_context\n",
      "    output_value = func(*func_args, **func_kwargs)  # %% callback invoked %%\n",
      "  File \"C:\\Users\\admin\\AppData\\Local\\Temp\\ipykernel_16924\\2990508254.py\", line 19, in stock_update\n",
      "    df=pdd.DataReader(stock_ticker,'iex',start,end)\n",
      "  File \"C:\\Users\\admin\\anaconda3\\lib\\site-packages\\pandas\\util\\_decorators.py\", line 207, in wrapper\n",
      "    return func(*args, **kwargs)\n",
      "  File \"C:\\Users\\admin\\anaconda3\\lib\\site-packages\\pandas_datareader\\data.py\", line 382, in DataReader\n",
      "    return IEXDailyReader(\n",
      "  File \"C:\\Users\\admin\\anaconda3\\lib\\site-packages\\pandas_datareader\\iex\\daily.py\", line 143, in read\n",
      "    return self._read_one_data(self.url, self._get_params(self.symbols))\n",
      "  File \"C:\\Users\\admin\\anaconda3\\lib\\site-packages\\pandas_datareader\\base.py\", line 108, in _read_one_data\n",
      "    out = self._read_url_as_StringIO(url, params=params)\n",
      "  File \"C:\\Users\\admin\\anaconda3\\lib\\site-packages\\pandas_datareader\\base.py\", line 119, in _read_url_as_StringIO\n",
      "    response = self._get_response(url, params=params)\n",
      "  File \"C:\\Users\\admin\\anaconda3\\lib\\site-packages\\pandas_datareader\\base.py\", line 181, in _get_response\n",
      "    raise RemoteDataError(msg)\n",
      "pandas_datareader._utils.RemoteDataError: Unable to read URL: https://cloud.iexapis.com/stable/stock/market/batch?symbols=NF&types=chart&range=max&token=pk_e124697d80704446893c52da182883c8\n"
     ]
    },
    {
     "name": "stderr",
     "output_type": "stream",
     "text": [
      "127.0.0.1 - - [03/Jan/2023 02:05:15] \"POST /_dash-update-component HTTP/1.1\" 500 -\n"
     ]
    },
    {
     "name": "stdout",
     "output_type": "stream",
     "text": [
      "Exception on /_dash-update-component [POST]\n",
      "Traceback (most recent call last):\n",
      "  File \"C:\\Users\\admin\\anaconda3\\lib\\site-packages\\flask\\app.py\", line 2447, in wsgi_app\n",
      "    response = self.full_dispatch_request()\n",
      "  File \"C:\\Users\\admin\\anaconda3\\lib\\site-packages\\flask\\app.py\", line 1952, in full_dispatch_request\n",
      "    rv = self.handle_user_exception(e)\n",
      "  File \"C:\\Users\\admin\\anaconda3\\lib\\site-packages\\flask\\app.py\", line 1821, in handle_user_exception\n",
      "    reraise(exc_type, exc_value, tb)\n",
      "  File \"C:\\Users\\admin\\anaconda3\\lib\\site-packages\\flask\\_compat.py\", line 39, in reraise\n",
      "    raise value\n",
      "  File \"C:\\Users\\admin\\anaconda3\\lib\\site-packages\\flask\\app.py\", line 1950, in full_dispatch_request\n",
      "    rv = self.dispatch_request()\n",
      "  File \"C:\\Users\\admin\\anaconda3\\lib\\site-packages\\flask\\app.py\", line 1936, in dispatch_request\n",
      "    return self.view_functions[rule.endpoint](**req.view_args)\n",
      "  File \"C:\\Users\\admin\\anaconda3\\lib\\site-packages\\dash\\dash.py\", line 1274, in dispatch\n",
      "    ctx.run(\n",
      "  File \"C:\\Users\\admin\\anaconda3\\lib\\site-packages\\dash\\_callback.py\", line 440, in add_context\n",
      "    output_value = func(*func_args, **func_kwargs)  # %% callback invoked %%\n",
      "  File \"C:\\Users\\admin\\AppData\\Local\\Temp\\ipykernel_16924\\2990508254.py\", line 19, in stock_update\n",
      "    df=pdd.DataReader(stock_ticker,'iex',start,end)\n",
      "  File \"C:\\Users\\admin\\anaconda3\\lib\\site-packages\\pandas\\util\\_decorators.py\", line 207, in wrapper\n",
      "    return func(*args, **kwargs)\n",
      "  File \"C:\\Users\\admin\\anaconda3\\lib\\site-packages\\pandas_datareader\\data.py\", line 382, in DataReader\n",
      "    return IEXDailyReader(\n",
      "  File \"C:\\Users\\admin\\anaconda3\\lib\\site-packages\\pandas_datareader\\iex\\daily.py\", line 143, in read\n",
      "    return self._read_one_data(self.url, self._get_params(self.symbols))\n",
      "  File \"C:\\Users\\admin\\anaconda3\\lib\\site-packages\\pandas_datareader\\base.py\", line 113, in _read_one_data\n",
      "    return self._read_lines(out)\n",
      "  File \"C:\\Users\\admin\\anaconda3\\lib\\site-packages\\pandas_datareader\\iex\\daily.py\", line 158, in _read_lines\n",
      "    df.set_index(\"date\", inplace=True)\n",
      "  File \"C:\\Users\\admin\\anaconda3\\lib\\site-packages\\pandas\\util\\_decorators.py\", line 311, in wrapper\n",
      "    return func(*args, **kwargs)\n",
      "  File \"C:\\Users\\admin\\anaconda3\\lib\\site-packages\\pandas\\core\\frame.py\", line 5494, in set_index\n",
      "    raise KeyError(f\"None of {missing} are in the columns\")\n",
      "KeyError: \"None of ['date'] are in the columns\"\n"
     ]
    },
    {
     "name": "stderr",
     "output_type": "stream",
     "text": [
      "127.0.0.1 - - [03/Jan/2023 02:05:16] \"POST /_dash-update-component HTTP/1.1\" 500 -\n",
      "127.0.0.1 - - [03/Jan/2023 02:05:17] \"POST /_dash-update-component HTTP/1.1\" 200 -\n"
     ]
    },
    {
     "name": "stdout",
     "output_type": "stream",
     "text": [
      "Exception on /_dash-update-component [POST]\n",
      "Traceback (most recent call last):\n",
      "  File \"C:\\Users\\admin\\anaconda3\\lib\\site-packages\\flask\\app.py\", line 2447, in wsgi_app\n",
      "    response = self.full_dispatch_request()\n",
      "  File \"C:\\Users\\admin\\anaconda3\\lib\\site-packages\\flask\\app.py\", line 1952, in full_dispatch_request\n",
      "    rv = self.handle_user_exception(e)\n",
      "  File \"C:\\Users\\admin\\anaconda3\\lib\\site-packages\\flask\\app.py\", line 1821, in handle_user_exception\n",
      "    reraise(exc_type, exc_value, tb)\n",
      "  File \"C:\\Users\\admin\\anaconda3\\lib\\site-packages\\flask\\_compat.py\", line 39, in reraise\n",
      "    raise value\n",
      "  File \"C:\\Users\\admin\\anaconda3\\lib\\site-packages\\flask\\app.py\", line 1950, in full_dispatch_request\n",
      "    rv = self.dispatch_request()\n",
      "  File \"C:\\Users\\admin\\anaconda3\\lib\\site-packages\\flask\\app.py\", line 1936, in dispatch_request\n",
      "    return self.view_functions[rule.endpoint](**req.view_args)\n",
      "  File \"C:\\Users\\admin\\anaconda3\\lib\\site-packages\\dash\\dash.py\", line 1274, in dispatch\n",
      "    ctx.run(\n",
      "  File \"C:\\Users\\admin\\anaconda3\\lib\\site-packages\\dash\\_callback.py\", line 440, in add_context\n",
      "    output_value = func(*func_args, **func_kwargs)  # %% callback invoked %%\n",
      "  File \"C:\\Users\\admin\\AppData\\Local\\Temp\\ipykernel_16924\\2990508254.py\", line 19, in stock_update\n",
      "    df=pdd.DataReader(stock_ticker,'iex',start,end)\n",
      "  File \"C:\\Users\\admin\\anaconda3\\lib\\site-packages\\pandas\\util\\_decorators.py\", line 207, in wrapper\n",
      "    return func(*args, **kwargs)\n",
      "  File \"C:\\Users\\admin\\anaconda3\\lib\\site-packages\\pandas_datareader\\data.py\", line 382, in DataReader\n",
      "    return IEXDailyReader(\n",
      "  File \"C:\\Users\\admin\\anaconda3\\lib\\site-packages\\pandas_datareader\\iex\\daily.py\", line 143, in read\n",
      "    return self._read_one_data(self.url, self._get_params(self.symbols))\n",
      "  File \"C:\\Users\\admin\\anaconda3\\lib\\site-packages\\pandas_datareader\\base.py\", line 108, in _read_one_data\n",
      "    out = self._read_url_as_StringIO(url, params=params)\n",
      "  File \"C:\\Users\\admin\\anaconda3\\lib\\site-packages\\pandas_datareader\\base.py\", line 119, in _read_url_as_StringIO\n",
      "    response = self._get_response(url, params=params)\n",
      "  File \"C:\\Users\\admin\\anaconda3\\lib\\site-packages\\pandas_datareader\\base.py\", line 181, in _get_response\n",
      "    raise RemoteDataError(msg)\n",
      "pandas_datareader._utils.RemoteDataError: Unable to read URL: https://cloud.iexapis.com/stable/stock/market/batch?symbols=HUU&types=chart&range=max&token=pk_e124697d80704446893c52da182883c8\n"
     ]
    },
    {
     "name": "stderr",
     "output_type": "stream",
     "text": [
      "127.0.0.1 - - [03/Jan/2023 02:05:18] \"POST /_dash-update-component HTTP/1.1\" 500 -\n"
     ]
    },
    {
     "name": "stdout",
     "output_type": "stream",
     "text": [
      "Exception on /_dash-update-component [POST]\n",
      "Traceback (most recent call last):\n",
      "  File \"C:\\Users\\admin\\anaconda3\\lib\\site-packages\\flask\\app.py\", line 2447, in wsgi_app\n",
      "    response = self.full_dispatch_request()\n",
      "  File \"C:\\Users\\admin\\anaconda3\\lib\\site-packages\\flask\\app.py\", line 1952, in full_dispatch_request\n",
      "    rv = self.handle_user_exception(e)\n",
      "  File \"C:\\Users\\admin\\anaconda3\\lib\\site-packages\\flask\\app.py\", line 1821, in handle_user_exception\n",
      "    reraise(exc_type, exc_value, tb)\n",
      "  File \"C:\\Users\\admin\\anaconda3\\lib\\site-packages\\flask\\_compat.py\", line 39, in reraise\n",
      "    raise value\n",
      "  File \"C:\\Users\\admin\\anaconda3\\lib\\site-packages\\flask\\app.py\", line 1950, in full_dispatch_request\n",
      "    rv = self.dispatch_request()\n",
      "  File \"C:\\Users\\admin\\anaconda3\\lib\\site-packages\\flask\\app.py\", line 1936, in dispatch_request\n",
      "    return self.view_functions[rule.endpoint](**req.view_args)\n",
      "  File \"C:\\Users\\admin\\anaconda3\\lib\\site-packages\\dash\\dash.py\", line 1274, in dispatch\n",
      "    ctx.run(\n",
      "  File \"C:\\Users\\admin\\anaconda3\\lib\\site-packages\\dash\\_callback.py\", line 440, in add_context\n",
      "    output_value = func(*func_args, **func_kwargs)  # %% callback invoked %%\n",
      "  File \"C:\\Users\\admin\\AppData\\Local\\Temp\\ipykernel_16924\\2990508254.py\", line 19, in stock_update\n",
      "    df=pdd.DataReader(stock_ticker,'iex',start,end)\n",
      "  File \"C:\\Users\\admin\\anaconda3\\lib\\site-packages\\pandas\\util\\_decorators.py\", line 207, in wrapper\n",
      "    return func(*args, **kwargs)\n",
      "  File \"C:\\Users\\admin\\anaconda3\\lib\\site-packages\\pandas_datareader\\data.py\", line 382, in DataReader\n",
      "    return IEXDailyReader(\n",
      "  File \"C:\\Users\\admin\\anaconda3\\lib\\site-packages\\pandas_datareader\\iex\\daily.py\", line 143, in read\n",
      "    return self._read_one_data(self.url, self._get_params(self.symbols))\n",
      "  File \"C:\\Users\\admin\\anaconda3\\lib\\site-packages\\pandas_datareader\\base.py\", line 108, in _read_one_data\n",
      "    out = self._read_url_as_StringIO(url, params=params)\n",
      "  File \"C:\\Users\\admin\\anaconda3\\lib\\site-packages\\pandas_datareader\\base.py\", line 119, in _read_url_as_StringIO\n",
      "    response = self._get_response(url, params=params)\n",
      "  File \"C:\\Users\\admin\\anaconda3\\lib\\site-packages\\pandas_datareader\\base.py\", line 181, in _get_response\n",
      "    raise RemoteDataError(msg)\n",
      "pandas_datareader._utils.RemoteDataError: Unable to read URL: https://cloud.iexapis.com/stable/stock/market/batch?symbols=HUUL&types=chart&range=max&token=pk_e124697d80704446893c52da182883c8\n"
     ]
    },
    {
     "name": "stderr",
     "output_type": "stream",
     "text": [
      "127.0.0.1 - - [03/Jan/2023 02:05:18] \"POST /_dash-update-component HTTP/1.1\" 500 -\n"
     ]
    },
    {
     "name": "stdout",
     "output_type": "stream",
     "text": [
      "Exception on /_dash-update-component [POST]\n",
      "Traceback (most recent call last):\n",
      "  File \"C:\\Users\\admin\\anaconda3\\lib\\site-packages\\flask\\app.py\", line 2447, in wsgi_app\n",
      "    response = self.full_dispatch_request()\n",
      "  File \"C:\\Users\\admin\\anaconda3\\lib\\site-packages\\flask\\app.py\", line 1952, in full_dispatch_request\n",
      "    rv = self.handle_user_exception(e)\n",
      "  File \"C:\\Users\\admin\\anaconda3\\lib\\site-packages\\flask\\app.py\", line 1821, in handle_user_exception\n",
      "    reraise(exc_type, exc_value, tb)\n",
      "  File \"C:\\Users\\admin\\anaconda3\\lib\\site-packages\\flask\\_compat.py\", line 39, in reraise\n",
      "    raise value\n",
      "  File \"C:\\Users\\admin\\anaconda3\\lib\\site-packages\\flask\\app.py\", line 1950, in full_dispatch_request\n",
      "    rv = self.dispatch_request()\n",
      "  File \"C:\\Users\\admin\\anaconda3\\lib\\site-packages\\flask\\app.py\", line 1936, in dispatch_request\n",
      "    return self.view_functions[rule.endpoint](**req.view_args)\n",
      "  File \"C:\\Users\\admin\\anaconda3\\lib\\site-packages\\dash\\dash.py\", line 1274, in dispatch\n",
      "    ctx.run(\n",
      "  File \"C:\\Users\\admin\\anaconda3\\lib\\site-packages\\dash\\_callback.py\", line 440, in add_context\n",
      "    output_value = func(*func_args, **func_kwargs)  # %% callback invoked %%\n",
      "  File \"C:\\Users\\admin\\AppData\\Local\\Temp\\ipykernel_16924\\2990508254.py\", line 19, in stock_update\n",
      "    df=pdd.DataReader(stock_ticker,'iex',start,end)\n",
      "  File \"C:\\Users\\admin\\anaconda3\\lib\\site-packages\\pandas\\util\\_decorators.py\", line 207, in wrapper\n",
      "    return func(*args, **kwargs)\n",
      "  File \"C:\\Users\\admin\\anaconda3\\lib\\site-packages\\pandas_datareader\\data.py\", line 382, in DataReader\n",
      "    return IEXDailyReader(\n",
      "  File \"C:\\Users\\admin\\anaconda3\\lib\\site-packages\\pandas_datareader\\iex\\daily.py\", line 143, in read\n",
      "    return self._read_one_data(self.url, self._get_params(self.symbols))\n",
      "  File \"C:\\Users\\admin\\anaconda3\\lib\\site-packages\\pandas_datareader\\base.py\", line 113, in _read_one_data\n",
      "    return self._read_lines(out)\n",
      "  File \"C:\\Users\\admin\\anaconda3\\lib\\site-packages\\pandas_datareader\\iex\\daily.py\", line 158, in _read_lines\n",
      "    df.set_index(\"date\", inplace=True)\n",
      "  File \"C:\\Users\\admin\\anaconda3\\lib\\site-packages\\pandas\\util\\_decorators.py\", line 311, in wrapper\n",
      "    return func(*args, **kwargs)\n",
      "  File \"C:\\Users\\admin\\anaconda3\\lib\\site-packages\\pandas\\core\\frame.py\", line 5494, in set_index\n",
      "    raise KeyError(f\"None of {missing} are in the columns\")\n",
      "KeyError: \"None of ['date'] are in the columns\"\n"
     ]
    },
    {
     "name": "stderr",
     "output_type": "stream",
     "text": [
      "127.0.0.1 - - [03/Jan/2023 02:06:00] \"POST /_dash-update-component HTTP/1.1\" 500 -\n"
     ]
    },
    {
     "name": "stdout",
     "output_type": "stream",
     "text": [
      "Exception on /_dash-update-component [POST]\n",
      "Traceback (most recent call last):\n",
      "  File \"C:\\Users\\admin\\anaconda3\\lib\\site-packages\\flask\\app.py\", line 2447, in wsgi_app\n",
      "    response = self.full_dispatch_request()\n",
      "  File \"C:\\Users\\admin\\anaconda3\\lib\\site-packages\\flask\\app.py\", line 1952, in full_dispatch_request\n",
      "    rv = self.handle_user_exception(e)\n",
      "  File \"C:\\Users\\admin\\anaconda3\\lib\\site-packages\\flask\\app.py\", line 1821, in handle_user_exception\n",
      "    reraise(exc_type, exc_value, tb)\n",
      "  File \"C:\\Users\\admin\\anaconda3\\lib\\site-packages\\flask\\_compat.py\", line 39, in reraise\n",
      "    raise value\n",
      "  File \"C:\\Users\\admin\\anaconda3\\lib\\site-packages\\flask\\app.py\", line 1950, in full_dispatch_request\n",
      "    rv = self.dispatch_request()\n",
      "  File \"C:\\Users\\admin\\anaconda3\\lib\\site-packages\\flask\\app.py\", line 1936, in dispatch_request\n",
      "    return self.view_functions[rule.endpoint](**req.view_args)\n",
      "  File \"C:\\Users\\admin\\anaconda3\\lib\\site-packages\\dash\\dash.py\", line 1274, in dispatch\n",
      "    ctx.run(\n",
      "  File \"C:\\Users\\admin\\anaconda3\\lib\\site-packages\\dash\\_callback.py\", line 440, in add_context\n",
      "    output_value = func(*func_args, **func_kwargs)  # %% callback invoked %%\n",
      "  File \"C:\\Users\\admin\\AppData\\Local\\Temp\\ipykernel_16924\\2990508254.py\", line 19, in stock_update\n",
      "    df=pdd.DataReader(stock_ticker,'iex',start,end)\n",
      "  File \"C:\\Users\\admin\\anaconda3\\lib\\site-packages\\pandas\\util\\_decorators.py\", line 207, in wrapper\n",
      "    return func(*args, **kwargs)\n",
      "  File \"C:\\Users\\admin\\anaconda3\\lib\\site-packages\\pandas_datareader\\data.py\", line 382, in DataReader\n",
      "    return IEXDailyReader(\n",
      "  File \"C:\\Users\\admin\\anaconda3\\lib\\site-packages\\pandas_datareader\\iex\\daily.py\", line 143, in read\n",
      "    return self._read_one_data(self.url, self._get_params(self.symbols))\n",
      "  File \"C:\\Users\\admin\\anaconda3\\lib\\site-packages\\pandas_datareader\\base.py\", line 108, in _read_one_data\n",
      "    out = self._read_url_as_StringIO(url, params=params)\n",
      "  File \"C:\\Users\\admin\\anaconda3\\lib\\site-packages\\pandas_datareader\\base.py\", line 119, in _read_url_as_StringIO\n",
      "    response = self._get_response(url, params=params)\n",
      "  File \"C:\\Users\\admin\\anaconda3\\lib\\site-packages\\pandas_datareader\\base.py\", line 181, in _get_response\n",
      "    raise RemoteDataError(msg)\n",
      "pandas_datareader._utils.RemoteDataError: Unable to read URL: https://cloud.iexapis.com/stable/stock/market/batch?symbols=HUU&types=chart&range=max&token=pk_e124697d80704446893c52da182883c8\n"
     ]
    },
    {
     "name": "stderr",
     "output_type": "stream",
     "text": [
      "127.0.0.1 - - [03/Jan/2023 02:06:01] \"POST /_dash-update-component HTTP/1.1\" 500 -\n"
     ]
    },
    {
     "name": "stdout",
     "output_type": "stream",
     "text": [
      "Exception on /_dash-update-component [POST]\n",
      "Traceback (most recent call last):\n",
      "  File \"C:\\Users\\admin\\anaconda3\\lib\\site-packages\\flask\\app.py\", line 2447, in wsgi_app\n",
      "    response = self.full_dispatch_request()\n",
      "  File \"C:\\Users\\admin\\anaconda3\\lib\\site-packages\\flask\\app.py\", line 1952, in full_dispatch_request\n",
      "    rv = self.handle_user_exception(e)\n",
      "  File \"C:\\Users\\admin\\anaconda3\\lib\\site-packages\\flask\\app.py\", line 1821, in handle_user_exception\n",
      "    reraise(exc_type, exc_value, tb)\n",
      "  File \"C:\\Users\\admin\\anaconda3\\lib\\site-packages\\flask\\_compat.py\", line 39, in reraise\n",
      "    raise value\n",
      "  File \"C:\\Users\\admin\\anaconda3\\lib\\site-packages\\flask\\app.py\", line 1950, in full_dispatch_request\n",
      "    rv = self.dispatch_request()\n",
      "  File \"C:\\Users\\admin\\anaconda3\\lib\\site-packages\\flask\\app.py\", line 1936, in dispatch_request\n",
      "    return self.view_functions[rule.endpoint](**req.view_args)\n",
      "  File \"C:\\Users\\admin\\anaconda3\\lib\\site-packages\\dash\\dash.py\", line 1274, in dispatch\n",
      "    ctx.run(\n",
      "  File \"C:\\Users\\admin\\anaconda3\\lib\\site-packages\\dash\\_callback.py\", line 440, in add_context\n",
      "    output_value = func(*func_args, **func_kwargs)  # %% callback invoked %%\n",
      "  File \"C:\\Users\\admin\\AppData\\Local\\Temp\\ipykernel_16924\\2990508254.py\", line 19, in stock_update\n",
      "    df=pdd.DataReader(stock_ticker,'iex',start,end)\n",
      "  File \"C:\\Users\\admin\\anaconda3\\lib\\site-packages\\pandas\\util\\_decorators.py\", line 207, in wrapper\n",
      "    return func(*args, **kwargs)\n",
      "  File \"C:\\Users\\admin\\anaconda3\\lib\\site-packages\\pandas_datareader\\data.py\", line 382, in DataReader\n",
      "    return IEXDailyReader(\n",
      "  File \"C:\\Users\\admin\\anaconda3\\lib\\site-packages\\pandas_datareader\\iex\\daily.py\", line 143, in read\n",
      "    return self._read_one_data(self.url, self._get_params(self.symbols))\n",
      "  File \"C:\\Users\\admin\\anaconda3\\lib\\site-packages\\pandas_datareader\\base.py\", line 108, in _read_one_data\n",
      "    out = self._read_url_as_StringIO(url, params=params)\n",
      "  File \"C:\\Users\\admin\\anaconda3\\lib\\site-packages\\pandas_datareader\\base.py\", line 119, in _read_url_as_StringIO\n",
      "    response = self._get_response(url, params=params)\n",
      "  File \"C:\\Users\\admin\\anaconda3\\lib\\site-packages\\pandas_datareader\\base.py\", line 181, in _get_response\n",
      "    raise RemoteDataError(msg)\n",
      "pandas_datareader._utils.RemoteDataError: Unable to read URL: https://cloud.iexapis.com/stable/stock/market/batch?symbols=HUL&types=chart&range=max&token=pk_e124697d80704446893c52da182883c8\n"
     ]
    },
    {
     "name": "stderr",
     "output_type": "stream",
     "text": [
      "127.0.0.1 - - [03/Jan/2023 02:06:03] \"POST /_dash-update-component HTTP/1.1\" 500 -\n"
     ]
    },
    {
     "name": "stdout",
     "output_type": "stream",
     "text": [
      "Exception on /_dash-update-component [POST]\n",
      "Traceback (most recent call last):\n",
      "  File \"C:\\Users\\admin\\anaconda3\\lib\\site-packages\\flask\\app.py\", line 2447, in wsgi_app\n",
      "    response = self.full_dispatch_request()\n",
      "  File \"C:\\Users\\admin\\anaconda3\\lib\\site-packages\\flask\\app.py\", line 1952, in full_dispatch_request\n",
      "    rv = self.handle_user_exception(e)\n",
      "  File \"C:\\Users\\admin\\anaconda3\\lib\\site-packages\\flask\\app.py\", line 1821, in handle_user_exception\n",
      "    reraise(exc_type, exc_value, tb)\n",
      "  File \"C:\\Users\\admin\\anaconda3\\lib\\site-packages\\flask\\_compat.py\", line 39, in reraise\n",
      "    raise value\n",
      "  File \"C:\\Users\\admin\\anaconda3\\lib\\site-packages\\flask\\app.py\", line 1950, in full_dispatch_request\n",
      "    rv = self.dispatch_request()\n",
      "  File \"C:\\Users\\admin\\anaconda3\\lib\\site-packages\\flask\\app.py\", line 1936, in dispatch_request\n",
      "    return self.view_functions[rule.endpoint](**req.view_args)\n",
      "  File \"C:\\Users\\admin\\anaconda3\\lib\\site-packages\\dash\\dash.py\", line 1274, in dispatch\n",
      "    ctx.run(\n",
      "  File \"C:\\Users\\admin\\anaconda3\\lib\\site-packages\\dash\\_callback.py\", line 440, in add_context\n",
      "    output_value = func(*func_args, **func_kwargs)  # %% callback invoked %%\n",
      "  File \"C:\\Users\\admin\\AppData\\Local\\Temp\\ipykernel_16924\\2990508254.py\", line 19, in stock_update\n",
      "    df=pdd.DataReader(stock_ticker,'iex',start,end)\n",
      "  File \"C:\\Users\\admin\\anaconda3\\lib\\site-packages\\pandas\\util\\_decorators.py\", line 207, in wrapper\n",
      "    return func(*args, **kwargs)\n",
      "  File \"C:\\Users\\admin\\anaconda3\\lib\\site-packages\\pandas_datareader\\data.py\", line 382, in DataReader\n",
      "    return IEXDailyReader(\n",
      "  File \"C:\\Users\\admin\\anaconda3\\lib\\site-packages\\pandas_datareader\\iex\\daily.py\", line 143, in read\n",
      "    return self._read_one_data(self.url, self._get_params(self.symbols))\n",
      "  File \"C:\\Users\\admin\\anaconda3\\lib\\site-packages\\pandas_datareader\\base.py\", line 113, in _read_one_data\n",
      "    return self._read_lines(out)\n",
      "  File \"C:\\Users\\admin\\anaconda3\\lib\\site-packages\\pandas_datareader\\iex\\daily.py\", line 158, in _read_lines\n",
      "    df.set_index(\"date\", inplace=True)\n",
      "  File \"C:\\Users\\admin\\anaconda3\\lib\\site-packages\\pandas\\util\\_decorators.py\", line 311, in wrapper\n",
      "    return func(*args, **kwargs)\n",
      "  File \"C:\\Users\\admin\\anaconda3\\lib\\site-packages\\pandas\\core\\frame.py\", line 5494, in set_index\n",
      "    raise KeyError(f\"None of {missing} are in the columns\")\n",
      "KeyError: \"None of ['date'] are in the columns\"\n"
     ]
    },
    {
     "name": "stderr",
     "output_type": "stream",
     "text": [
      "127.0.0.1 - - [03/Jan/2023 02:06:06] \"POST /_dash-update-component HTTP/1.1\" 500 -\n"
     ]
    },
    {
     "name": "stdout",
     "output_type": "stream",
     "text": [
      "Exception on /_dash-update-component [POST]\n",
      "Traceback (most recent call last):\n",
      "  File \"C:\\Users\\admin\\anaconda3\\lib\\site-packages\\flask\\app.py\", line 2447, in wsgi_app\n",
      "    response = self.full_dispatch_request()\n",
      "  File \"C:\\Users\\admin\\anaconda3\\lib\\site-packages\\flask\\app.py\", line 1952, in full_dispatch_request\n",
      "    rv = self.handle_user_exception(e)\n",
      "  File \"C:\\Users\\admin\\anaconda3\\lib\\site-packages\\flask\\app.py\", line 1821, in handle_user_exception\n",
      "    reraise(exc_type, exc_value, tb)\n",
      "  File \"C:\\Users\\admin\\anaconda3\\lib\\site-packages\\flask\\_compat.py\", line 39, in reraise\n",
      "    raise value\n",
      "  File \"C:\\Users\\admin\\anaconda3\\lib\\site-packages\\flask\\app.py\", line 1950, in full_dispatch_request\n",
      "    rv = self.dispatch_request()\n",
      "  File \"C:\\Users\\admin\\anaconda3\\lib\\site-packages\\flask\\app.py\", line 1936, in dispatch_request\n",
      "    return self.view_functions[rule.endpoint](**req.view_args)\n",
      "  File \"C:\\Users\\admin\\anaconda3\\lib\\site-packages\\dash\\dash.py\", line 1274, in dispatch\n",
      "    ctx.run(\n",
      "  File \"C:\\Users\\admin\\anaconda3\\lib\\site-packages\\dash\\_callback.py\", line 440, in add_context\n",
      "    output_value = func(*func_args, **func_kwargs)  # %% callback invoked %%\n",
      "  File \"C:\\Users\\admin\\AppData\\Local\\Temp\\ipykernel_16924\\2990508254.py\", line 19, in stock_update\n",
      "    df=pdd.DataReader(stock_ticker,'iex',start,end)\n",
      "  File \"C:\\Users\\admin\\anaconda3\\lib\\site-packages\\pandas\\util\\_decorators.py\", line 207, in wrapper\n",
      "    return func(*args, **kwargs)\n",
      "  File \"C:\\Users\\admin\\anaconda3\\lib\\site-packages\\pandas_datareader\\data.py\", line 382, in DataReader\n",
      "    return IEXDailyReader(\n",
      "  File \"C:\\Users\\admin\\anaconda3\\lib\\site-packages\\pandas_datareader\\iex\\daily.py\", line 143, in read\n",
      "    return self._read_one_data(self.url, self._get_params(self.symbols))\n",
      "  File \"C:\\Users\\admin\\anaconda3\\lib\\site-packages\\pandas_datareader\\base.py\", line 108, in _read_one_data\n",
      "    out = self._read_url_as_StringIO(url, params=params)\n",
      "  File \"C:\\Users\\admin\\anaconda3\\lib\\site-packages\\pandas_datareader\\base.py\", line 119, in _read_url_as_StringIO\n",
      "    response = self._get_response(url, params=params)\n",
      "  File \"C:\\Users\\admin\\anaconda3\\lib\\site-packages\\pandas_datareader\\base.py\", line 181, in _get_response\n",
      "    raise RemoteDataError(msg)\n",
      "pandas_datareader._utils.RemoteDataError: Unable to read URL: https://cloud.iexapis.com/stable/stock/market/batch?symbols=&types=chart&range=max&token=pk_e124697d80704446893c52da182883c8\n",
      "Response Text:\n",
      "b'{\"error\":\"\\\\\"symbols\\\\\" is not allowed to be empty\"}'\n"
     ]
    },
    {
     "name": "stderr",
     "output_type": "stream",
     "text": [
      "127.0.0.1 - - [03/Jan/2023 02:06:08] \"POST /_dash-update-component HTTP/1.1\" 500 -\n",
      "127.0.0.1 - - [03/Jan/2023 02:06:08] \"POST /_dash-update-component HTTP/1.1\" 200 -\n"
     ]
    },
    {
     "name": "stdout",
     "output_type": "stream",
     "text": [
      "Exception on /_dash-update-component [POST]\n",
      "Traceback (most recent call last):\n",
      "  File \"C:\\Users\\admin\\anaconda3\\lib\\site-packages\\flask\\app.py\", line 2447, in wsgi_app\n",
      "    response = self.full_dispatch_request()\n",
      "  File \"C:\\Users\\admin\\anaconda3\\lib\\site-packages\\flask\\app.py\", line 1952, in full_dispatch_request\n",
      "    rv = self.handle_user_exception(e)\n",
      "  File \"C:\\Users\\admin\\anaconda3\\lib\\site-packages\\flask\\app.py\", line 1821, in handle_user_exception\n",
      "    reraise(exc_type, exc_value, tb)\n",
      "  File \"C:\\Users\\admin\\anaconda3\\lib\\site-packages\\flask\\_compat.py\", line 39, in reraise\n",
      "    raise value\n",
      "  File \"C:\\Users\\admin\\anaconda3\\lib\\site-packages\\flask\\app.py\", line 1950, in full_dispatch_request\n",
      "    rv = self.dispatch_request()\n",
      "  File \"C:\\Users\\admin\\anaconda3\\lib\\site-packages\\flask\\app.py\", line 1936, in dispatch_request\n",
      "    return self.view_functions[rule.endpoint](**req.view_args)\n",
      "  File \"C:\\Users\\admin\\anaconda3\\lib\\site-packages\\dash\\dash.py\", line 1274, in dispatch\n",
      "    ctx.run(\n",
      "  File \"C:\\Users\\admin\\anaconda3\\lib\\site-packages\\dash\\_callback.py\", line 440, in add_context\n",
      "    output_value = func(*func_args, **func_kwargs)  # %% callback invoked %%\n",
      "  File \"C:\\Users\\admin\\AppData\\Local\\Temp\\ipykernel_16924\\2990508254.py\", line 19, in stock_update\n",
      "    df=pdd.DataReader(stock_ticker,'iex',start,end)\n",
      "  File \"C:\\Users\\admin\\anaconda3\\lib\\site-packages\\pandas\\util\\_decorators.py\", line 207, in wrapper\n",
      "    return func(*args, **kwargs)\n",
      "  File \"C:\\Users\\admin\\anaconda3\\lib\\site-packages\\pandas_datareader\\data.py\", line 382, in DataReader\n",
      "    return IEXDailyReader(\n",
      "  File \"C:\\Users\\admin\\anaconda3\\lib\\site-packages\\pandas_datareader\\iex\\daily.py\", line 143, in read\n",
      "    return self._read_one_data(self.url, self._get_params(self.symbols))\n",
      "  File \"C:\\Users\\admin\\anaconda3\\lib\\site-packages\\pandas_datareader\\base.py\", line 113, in _read_one_data\n",
      "    return self._read_lines(out)\n",
      "  File \"C:\\Users\\admin\\anaconda3\\lib\\site-packages\\pandas_datareader\\iex\\daily.py\", line 158, in _read_lines\n",
      "    df.set_index(\"date\", inplace=True)\n",
      "  File \"C:\\Users\\admin\\anaconda3\\lib\\site-packages\\pandas\\util\\_decorators.py\", line 311, in wrapper\n",
      "    return func(*args, **kwargs)\n",
      "  File \"C:\\Users\\admin\\anaconda3\\lib\\site-packages\\pandas\\core\\frame.py\", line 5494, in set_index\n",
      "    raise KeyError(f\"None of {missing} are in the columns\")\n",
      "KeyError: \"None of ['date'] are in the columns\"\n"
     ]
    },
    {
     "name": "stderr",
     "output_type": "stream",
     "text": [
      "127.0.0.1 - - [03/Jan/2023 02:06:08] \"POST /_dash-update-component HTTP/1.1\" 500 -\n",
      "127.0.0.1 - - [03/Jan/2023 02:06:09] \"POST /_dash-update-component HTTP/1.1\" 200 -\n",
      "127.0.0.1 - - [03/Jan/2023 02:06:10] \"POST /_dash-update-component HTTP/1.1\" 200 -\n",
      "127.0.0.1 - - [03/Jan/2023 02:06:10] \"POST /_dash-update-component HTTP/1.1\" 200 -\n"
     ]
    },
    {
     "name": "stdout",
     "output_type": "stream",
     "text": [
      "Exception on /_dash-update-component [POST]\n",
      "Traceback (most recent call last):\n",
      "  File \"C:\\Users\\admin\\anaconda3\\lib\\site-packages\\flask\\app.py\", line 2447, in wsgi_app\n",
      "    response = self.full_dispatch_request()\n",
      "  File \"C:\\Users\\admin\\anaconda3\\lib\\site-packages\\flask\\app.py\", line 1952, in full_dispatch_request\n",
      "    rv = self.handle_user_exception(e)\n",
      "  File \"C:\\Users\\admin\\anaconda3\\lib\\site-packages\\flask\\app.py\", line 1821, in handle_user_exception\n",
      "    reraise(exc_type, exc_value, tb)\n",
      "  File \"C:\\Users\\admin\\anaconda3\\lib\\site-packages\\flask\\_compat.py\", line 39, in reraise\n",
      "    raise value\n",
      "  File \"C:\\Users\\admin\\anaconda3\\lib\\site-packages\\flask\\app.py\", line 1950, in full_dispatch_request\n",
      "    rv = self.dispatch_request()\n",
      "  File \"C:\\Users\\admin\\anaconda3\\lib\\site-packages\\flask\\app.py\", line 1936, in dispatch_request\n",
      "    return self.view_functions[rule.endpoint](**req.view_args)\n",
      "  File \"C:\\Users\\admin\\anaconda3\\lib\\site-packages\\dash\\dash.py\", line 1274, in dispatch\n",
      "    ctx.run(\n",
      "  File \"C:\\Users\\admin\\anaconda3\\lib\\site-packages\\dash\\_callback.py\", line 440, in add_context\n",
      "    output_value = func(*func_args, **func_kwargs)  # %% callback invoked %%\n",
      "  File \"C:\\Users\\admin\\AppData\\Local\\Temp\\ipykernel_16924\\2990508254.py\", line 19, in stock_update\n",
      "    df=pdd.DataReader(stock_ticker,'iex',start,end)\n",
      "  File \"C:\\Users\\admin\\anaconda3\\lib\\site-packages\\pandas\\util\\_decorators.py\", line 207, in wrapper\n",
      "    return func(*args, **kwargs)\n",
      "  File \"C:\\Users\\admin\\anaconda3\\lib\\site-packages\\pandas_datareader\\data.py\", line 382, in DataReader\n",
      "    return IEXDailyReader(\n",
      "  File \"C:\\Users\\admin\\anaconda3\\lib\\site-packages\\pandas_datareader\\iex\\daily.py\", line 143, in read\n",
      "    return self._read_one_data(self.url, self._get_params(self.symbols))\n",
      "  File \"C:\\Users\\admin\\anaconda3\\lib\\site-packages\\pandas_datareader\\base.py\", line 113, in _read_one_data\n",
      "    return self._read_lines(out)\n",
      "  File \"C:\\Users\\admin\\anaconda3\\lib\\site-packages\\pandas_datareader\\iex\\daily.py\", line 158, in _read_lines\n",
      "    df.set_index(\"date\", inplace=True)\n",
      "  File \"C:\\Users\\admin\\anaconda3\\lib\\site-packages\\pandas\\util\\_decorators.py\", line 311, in wrapper\n",
      "    return func(*args, **kwargs)\n",
      "  File \"C:\\Users\\admin\\anaconda3\\lib\\site-packages\\pandas\\core\\frame.py\", line 5494, in set_index\n",
      "    raise KeyError(f\"None of {missing} are in the columns\")\n",
      "KeyError: \"None of ['date'] are in the columns\"\n"
     ]
    },
    {
     "name": "stderr",
     "output_type": "stream",
     "text": [
      "127.0.0.1 - - [03/Jan/2023 02:06:30] \"POST /_dash-update-component HTTP/1.1\" 500 -\n",
      "127.0.0.1 - - [03/Jan/2023 02:06:32] \"POST /_dash-update-component HTTP/1.1\" 200 -\n"
     ]
    },
    {
     "name": "stdout",
     "output_type": "stream",
     "text": [
      "Exception on /_dash-update-component [POST]\n",
      "Traceback (most recent call last):\n",
      "  File \"C:\\Users\\admin\\anaconda3\\lib\\site-packages\\flask\\app.py\", line 2447, in wsgi_app\n",
      "    response = self.full_dispatch_request()\n",
      "  File \"C:\\Users\\admin\\anaconda3\\lib\\site-packages\\flask\\app.py\", line 1952, in full_dispatch_request\n",
      "    rv = self.handle_user_exception(e)\n",
      "  File \"C:\\Users\\admin\\anaconda3\\lib\\site-packages\\flask\\app.py\", line 1821, in handle_user_exception\n",
      "    reraise(exc_type, exc_value, tb)\n",
      "  File \"C:\\Users\\admin\\anaconda3\\lib\\site-packages\\flask\\_compat.py\", line 39, in reraise\n",
      "    raise value\n",
      "  File \"C:\\Users\\admin\\anaconda3\\lib\\site-packages\\flask\\app.py\", line 1950, in full_dispatch_request\n",
      "    rv = self.dispatch_request()\n",
      "  File \"C:\\Users\\admin\\anaconda3\\lib\\site-packages\\flask\\app.py\", line 1936, in dispatch_request\n",
      "    return self.view_functions[rule.endpoint](**req.view_args)\n",
      "  File \"C:\\Users\\admin\\anaconda3\\lib\\site-packages\\dash\\dash.py\", line 1274, in dispatch\n",
      "    ctx.run(\n",
      "  File \"C:\\Users\\admin\\anaconda3\\lib\\site-packages\\dash\\_callback.py\", line 440, in add_context\n",
      "    output_value = func(*func_args, **func_kwargs)  # %% callback invoked %%\n",
      "  File \"C:\\Users\\admin\\AppData\\Local\\Temp\\ipykernel_16924\\2990508254.py\", line 19, in stock_update\n",
      "    df=pdd.DataReader(stock_ticker,'iex',start,end)\n",
      "  File \"C:\\Users\\admin\\anaconda3\\lib\\site-packages\\pandas\\util\\_decorators.py\", line 207, in wrapper\n",
      "    return func(*args, **kwargs)\n",
      "  File \"C:\\Users\\admin\\anaconda3\\lib\\site-packages\\pandas_datareader\\data.py\", line 382, in DataReader\n",
      "    return IEXDailyReader(\n",
      "  File \"C:\\Users\\admin\\anaconda3\\lib\\site-packages\\pandas_datareader\\iex\\daily.py\", line 143, in read\n",
      "    return self._read_one_data(self.url, self._get_params(self.symbols))\n",
      "  File \"C:\\Users\\admin\\anaconda3\\lib\\site-packages\\pandas_datareader\\base.py\", line 108, in _read_one_data\n",
      "    out = self._read_url_as_StringIO(url, params=params)\n",
      "  File \"C:\\Users\\admin\\anaconda3\\lib\\site-packages\\pandas_datareader\\base.py\", line 119, in _read_url_as_StringIO\n",
      "    response = self._get_response(url, params=params)\n",
      "  File \"C:\\Users\\admin\\anaconda3\\lib\\site-packages\\pandas_datareader\\base.py\", line 181, in _get_response\n",
      "    raise RemoteDataError(msg)\n",
      "pandas_datareader._utils.RemoteDataError: Unable to read URL: https://cloud.iexapis.com/stable/stock/market/batch?symbols=&types=chart&range=max&token=pk_e124697d80704446893c52da182883c8\n",
      "Response Text:\n",
      "b'{\"error\":\"\\\\\"symbols\\\\\" is not allowed to be empty\"}'\n"
     ]
    },
    {
     "name": "stderr",
     "output_type": "stream",
     "text": [
      "127.0.0.1 - - [03/Jan/2023 02:06:32] \"POST /_dash-update-component HTTP/1.1\" 500 -\n"
     ]
    },
    {
     "name": "stdout",
     "output_type": "stream",
     "text": [
      "Exception on /_dash-update-component [POST]\n",
      "Traceback (most recent call last):\n",
      "  File \"C:\\Users\\admin\\anaconda3\\lib\\site-packages\\flask\\app.py\", line 2447, in wsgi_app\n",
      "    response = self.full_dispatch_request()\n",
      "  File \"C:\\Users\\admin\\anaconda3\\lib\\site-packages\\flask\\app.py\", line 1952, in full_dispatch_request\n",
      "    rv = self.handle_user_exception(e)\n",
      "  File \"C:\\Users\\admin\\anaconda3\\lib\\site-packages\\flask\\app.py\", line 1821, in handle_user_exception\n",
      "    reraise(exc_type, exc_value, tb)\n",
      "  File \"C:\\Users\\admin\\anaconda3\\lib\\site-packages\\flask\\_compat.py\", line 39, in reraise\n",
      "    raise value\n",
      "  File \"C:\\Users\\admin\\anaconda3\\lib\\site-packages\\flask\\app.py\", line 1950, in full_dispatch_request\n",
      "    rv = self.dispatch_request()\n",
      "  File \"C:\\Users\\admin\\anaconda3\\lib\\site-packages\\flask\\app.py\", line 1936, in dispatch_request\n",
      "    return self.view_functions[rule.endpoint](**req.view_args)\n",
      "  File \"C:\\Users\\admin\\anaconda3\\lib\\site-packages\\dash\\dash.py\", line 1274, in dispatch\n",
      "    ctx.run(\n",
      "  File \"C:\\Users\\admin\\anaconda3\\lib\\site-packages\\dash\\_callback.py\", line 440, in add_context\n",
      "    output_value = func(*func_args, **func_kwargs)  # %% callback invoked %%\n",
      "  File \"C:\\Users\\admin\\AppData\\Local\\Temp\\ipykernel_16924\\2990508254.py\", line 19, in stock_update\n",
      "    df=pdd.DataReader(stock_ticker,'iex',start,end)\n",
      "  File \"C:\\Users\\admin\\anaconda3\\lib\\site-packages\\pandas\\util\\_decorators.py\", line 207, in wrapper\n",
      "    return func(*args, **kwargs)\n",
      "  File \"C:\\Users\\admin\\anaconda3\\lib\\site-packages\\pandas_datareader\\data.py\", line 382, in DataReader\n",
      "    return IEXDailyReader(\n",
      "  File \"C:\\Users\\admin\\anaconda3\\lib\\site-packages\\pandas_datareader\\iex\\daily.py\", line 143, in read\n",
      "    return self._read_one_data(self.url, self._get_params(self.symbols))\n",
      "  File \"C:\\Users\\admin\\anaconda3\\lib\\site-packages\\pandas_datareader\\base.py\", line 113, in _read_one_data\n",
      "    return self._read_lines(out)\n",
      "  File \"C:\\Users\\admin\\anaconda3\\lib\\site-packages\\pandas_datareader\\iex\\daily.py\", line 158, in _read_lines\n",
      "    df.set_index(\"date\", inplace=True)\n",
      "  File \"C:\\Users\\admin\\anaconda3\\lib\\site-packages\\pandas\\util\\_decorators.py\", line 311, in wrapper\n",
      "    return func(*args, **kwargs)\n",
      "  File \"C:\\Users\\admin\\anaconda3\\lib\\site-packages\\pandas\\core\\frame.py\", line 5494, in set_index\n",
      "    raise KeyError(f\"None of {missing} are in the columns\")\n",
      "KeyError: \"None of ['date'] are in the columns\"\n"
     ]
    },
    {
     "name": "stderr",
     "output_type": "stream",
     "text": [
      "127.0.0.1 - - [03/Jan/2023 02:06:33] \"POST /_dash-update-component HTTP/1.1\" 500 -\n",
      "127.0.0.1 - - [03/Jan/2023 02:06:33] \"POST /_dash-update-component HTTP/1.1\" 200 -\n",
      "127.0.0.1 - - [03/Jan/2023 02:06:35] \"POST /_dash-update-component HTTP/1.1\" 200 -\n",
      "127.0.0.1 - - [03/Jan/2023 02:06:36] \"POST /_dash-update-component HTTP/1.1\" 200 -\n",
      "127.0.0.1 - - [03/Jan/2023 02:06:36] \"POST /_dash-update-component HTTP/1.1\" 200 -\n"
     ]
    }
   ],
   "source": [
    "\n",
    "\n",
    "app=dash.Dash()\n",
    "\n",
    "app.layout= html.Div([\n",
    "                html.H1('Stock Ticker Dashboard'),\n",
    "                html.H2('Enter a stock symbol'),\n",
    "                dcc.Input(id='my_stock_picker',value='TSLA'),\n",
    "                dcc.Graph(id='my_graph',\n",
    "                          figure={'data':[{'x':[1,2],'y':[2,1]}],\n",
    "                                 'layout':{'title':'Default Title'}}\n",
    "                                  )\n",
    "                \n",
    "            ],style={'background-color': '#efefef','margin-left': '10'})\n",
    "\n",
    "@app.callback(Output('my_graph','figure'),\n",
    "             [Input('my_stock_picker','value')])\n",
    "def stock_update(stock_ticker):\n",
    "    start=datetime(2017,1,1)\n",
    "    end=datetime(2017,12,31)\n",
    "    df=pdd.DataReader(stock_ticker,'iex',start,end)\n",
    "    fig={'data':[{'x':df.index,'y':df.close}],\n",
    "        'layout':{'title': stock_ticker}\n",
    "        \n",
    "    }\n",
    "    return fig\n",
    "\n",
    "if __name__ == '__main__':\n",
    "    app.run_server()\n"
   ]
  },
  {
   "cell_type": "code",
   "execution_count": null,
   "id": "cc0da6a1",
   "metadata": {},
   "outputs": [],
   "source": []
  }
 ],
 "metadata": {
  "kernelspec": {
   "display_name": "Python 3 (ipykernel)",
   "language": "python",
   "name": "python3"
  },
  "language_info": {
   "codemirror_mode": {
    "name": "ipython",
    "version": 3
   },
   "file_extension": ".py",
   "mimetype": "text/x-python",
   "name": "python",
   "nbconvert_exporter": "python",
   "pygments_lexer": "ipython3",
   "version": "3.9.12"
  }
 },
 "nbformat": 4,
 "nbformat_minor": 5
}
